Workbook

Sheet 2026
B1: 46023 | C1: 46054 | D1: 46082 | E1: 46113 | F1: 46143 | G1: 46174 | H1: 46204 | I1: 46235 | J1: 46266 | K1: 46296 | L1: 46327 | M1: 46357 | N1: TOTAL
A2: Usuários | B2: =Dados!B1 -> 10 | C2: =ROUNDDOWN(Dados!$B$1+(B2-(B2*Dados!$B$3)),0) -> 19 | D2: =ROUNDDOWN(Dados!$B$1+(C2-(C2*Dados!$B$3)),0) -> 28 | E2: =ROUNDDOWN(Dados!$B$1+(D2-(D2*Dados!$B$3)),0) -> 37 | F2: =ROUNDDOWN(Dados!$B$1+(E2-(E2*Dados!$B$3)),0) -> 46 | G2: =ROUNDDOWN(Dados!$B$1+(F2-(F2*Dados!$B$3)),0) -> 55 | H2: =ROUNDDOWN(Dados!$B$1+(G2-(G2*Dados!$B$3)),0) -> 63 | I2: =ROUNDDOWN(Dados!$B$1+(H2-(H2*Dados!$B$3)),0) -> 71 | J2: =ROUNDDOWN(Dados!$B$1+(I2-(I2*Dados!$B$3)),0) -> 79 | ... M2: =ROUNDDOWN(Dados!$B$1+(L2-(L2*Dados!$B$3)),0) -> 103 | N2: =M2 -> 103
A4: Receita Total | B4: =ROUND(B5+B6,2) -> 8358 | C4: =ROUND(C5+C6,2) -> 15880.2 | D4: =ROUND(D5+D6,2) -> 23402.4 | E4: =ROUND(E5+E6,2) -> 30924.6 | F4: =ROUND(F5+F6,2) -> 38446.8 | G4: =ROUND(G5+G6,2) -> 45969 | H4: =ROUND(H5+H6,2) -> 52655.4 | I4: =ROUND(I5+I6,2) -> 59341.8 | ... M4: =ROUND(M5+M6,2) -> 86087.4 | N4: =ROUND(SUM(B4:M4),2) -> 579209.4
A5: Receita Fixa - Mensalidade | B5: =ROUND(B2*Dados!$B$5,0) -> 5970 | C5: =ROUND(C2*Dados!$B$5,0) -> 11343 | D5: =ROUND(D2*Dados!$B$5,0) -> 16716 | E5: =ROUND(E2*Dados!$B$5,0) -> 22089 | F5: =ROUND(F2*Dados!$B$5,0) -> 27462 | G5: =ROUND(G2*Dados!$B$5,0) -> 32835 | H5: =ROUND(H2*Dados!$B$5,0) -> 37611 | I5: =ROUND(I2*Dados!$B$5,0) -> 42387 | ... M5: =ROUND(M2*Dados!$B$5,0) -> 61491 | N5: =ROUND(SUM(B5:M5),2) -> 413721
A6: Receita Variável - Comissão sobre Vendas Recuperadas | B6: =IF(Dados!$B$9>0,Dados!$B$9*B2,ROUND(B2*(Dados!$B$11*Dados!$B$7),2)) -> 2388 | C6: =IF(Dados!$B$9>0,Dados!$B$9*C2,ROUND(C2*(Dados!$B$11*Dados!$B$7),2)) -> 4537.2 | D6: =IF(Dados!$B$9>0,Dados!$B$9*D2,ROUND(D2*(Dados!$B$11*Dados!$B$7),2)) -> 6686.4 | E6: =IF(Dados!$B$9>0,Dados!$B$9*E2,ROUND(E2*(Dados!$B$11*Dados!$B$7),2)) -> 8835.6 | F6: =IF(Dados!$B$9>0,Dados!$B$9*F2,ROUND(F2*(Dados!$B$11*Dados!$B$7),2)) -> 10984.8 | G6: =IF(Dados!$B$9>0,Dados!$B$9*G2,ROUND(G2*(Dados!$B$11*Dados!$B$7),2)) -> 13134 | H6: =IF(Dados!$B$9>0,Dados!$B$9*H2,ROUND(H2*(Dados!$B$11*Dados!$B$7),2)) -> 15044.4 | I6: =IF(Dados!$B$9>0,Dados!$B$9*I2,ROUND(I2*(Dados!$B$11*Dados!$B$7),2)) -> 16954.8 | ... M6: =IF(Dados!$B$9>0,Dados!$B$9*M2,ROUND(M2*(Dados!$B$11*Dados!$B$7),2)) -> 24596.4 | N6: =ROUND(SUM(B6:M6),2) -> 165488.4
A7: Impostos | B7: =B4*Dados!$E$2 -> 1337.28 | C7: =C4*Dados!$E$2 -> 2540.832 | D7: =D4*Dados!$E$2 -> 3744.384 | E7: =E4*Dados!$E$2 -> 4947.936 | F7: =F4*Dados!$E$2 -> 6151.488 | G7: =G4*Dados!$E$2 -> 7355.04 | H7: =H4*Dados!$E$2 -> 8424.864 | I7: =I4*Dados!$E$2 -> 9494.688 | ... M7: =M4*Dados!$E$2 -> 13773.984 | N7: =ROUND(SUM(B7:M7),2) -> 92673.5
A8: Receita Líquida | B8: =B4-B7 -> 7020.72 | C8: =C4-C7 -> 13339.368 | D8: =D4-D7 -> 19658.016 | E8: =E4-E7 -> 25976.664 | F8: =F4-F7 -> 32295.312 | G8: =G4-G7 -> 38613.96 | H8: =H4-H7 -> 44230.536 | I8: =I4-I7 -> 49847.112 | ... M8: =M4-M7 -> 72313.416 | N8: =ROUND(SUM(B8:M8),2) -> 486535.9
A9: Resultado Bruto | B9: =ROUND(B8-B14-B15-B16-B17-B18,2) -> 4222.22 | C9: =ROUND(C8-C14-C15-C16-C17-C18,2) -> 8022.22 | D9: =ROUND(D8-D14-D15-D16-D17-D18,2) -> 11822.22 | E9: =ROUND(E8-E14-E15-E16-E17-E18,2) -> 15622.21 | F9: =ROUND(F8-F14-F15-F16-F17-F18,2) -> 19422.21 | G9: =ROUND(G8-G14-G15-G16-G17-G18,2) -> 23222.21 | H9: =ROUND(H8-H14-H15-H16-H17-H18,2) -> 26599.99 | I9: =ROUND(I8-I14-I15-I16-I17-I18,2) -> 29977.76 | ... M9: =ROUND(M8-M14-M15-M16-M17-M18,2) -> 43488.87 | N9: =ROUND(SUM(B9:M9),2) -> 292599.85
A10: Margem Bruta % | B10: =IFERROR(ROUND(B9/B4,2),0) -> 0.51 | C10: =IFERROR(ROUND(C9/C4,2),0) -> 0.51 | D10: =IFERROR(ROUND(D9/D4,2),0) -> 0.51 | E10: =IFERROR(ROUND(E9/E4,2),0) -> 0.51 | F10: =IFERROR(ROUND(F9/F4,2),0) -> 0.51 | G10: =IFERROR(ROUND(G9/G4,2),0) -> 0.51 | H10: =IFERROR(ROUND(H9/H4,2),0) -> 0.51 | I10: =IFERROR(ROUND(I9/I4,2),0) -> 0.51 | ... N10: =IFERROR(ROUND(N9/N4,2),0) -> 0.51
A12: Despesa Total | B12: =ROUND(SUM(B13,B19),2) -> 42546.5 | C12: =ROUND(SUM(C13,C19),2) -> 45097.15 | D12: =ROUND(SUM(D13,D19),2) -> 47615.8 | E12: =ROUND(SUM(E13,E19),2) -> 50134.45 | F12: =ROUND(SUM(F13,F19),2) -> 52653.1 | G12: =ROUND(SUM(G13,G19),2) -> 55171.75 | H12: =ROUND(SUM(H13,H19),2) -> 57410.55 | I12: =ROUND(SUM(I13,I19),2) -> 59649.35 | ... M12: =ROUND(SUM(M13,M19),2) -> 68604.55 | N12: =ROUND(SUM(B12:M12),2) -> 671264.05 | O12: =N12-N8 -> 184728.15
A13: Despesas Variáveis | B13: =B14+B15+B16+B17+B18 -> 2798.5 | C13: =C14+C15+C16+C17+C18 -> 5317.15 | D13: =D14+D15+D16+D17+D18 -> 7835.8 | E13: =E14+E15+E16+E17+E18 -> 10354.45 | F13: =F14+F15+F16+F17+F18 -> 12873.1 | G13: =G14+G15+G16+G17+G18 -> 15391.75 | H13: =H14+H15+H16+H17+H18 -> 17630.55 | I13: =I14+I15+I16+I17+I18 -> 19869.35 | ... M13: =M14+M15+M16+M17+M18 -> 28824.55 | N13: =ROUND(SUM(B13:M13),2) -> 193936.05
A14: Taxas de Checkout e Plataformas | B14: =B5*Dados!$E$1 -> 298.5 | C14: =C5*Dados!$E$1 -> 567.15 | D14: =D5*Dados!$E$1 -> 835.8 | E14: =E5*Dados!$E$1 -> 1104.45 | F14: =F5*Dados!$E$1 -> 1373.1 | G14: =G5*Dados!$E$1 -> 1641.75 | H14: =H5*Dados!$E$1 -> 1880.55 | I14: =I5*Dados!$E$1 -> 2119.35 | ... M14: =M5*Dados!$E$1 -> 3074.55 | N14: =ROUND(SUM(B14:M14),2) -> 20686.05
A15: Servidor | B15: =10*B2 -> 100 | C15: =10*C2 -> 190 | D15: =10*D2 -> 280 | E15: =10*E2 -> 370 | F15: =10*F2 -> 460 | G15: =10*G2 -> 550 | H15: =10*H2 -> 630 | I15: =10*I2 -> 710 | ... M15: =10*M2 -> 1030 | N15: =ROUND(SUM(B15:M15),2) -> 6930
A16: API Oficial Whatsapp | B16: =200*B2 -> 2000 | C16: =200*C2 -> 3800 | D16: =200*D2 -> 5600 | E16: =200*E2 -> 7400 | F16: =200*F2 -> 9200 | G16: =200*G2 -> 11000 | H16: =200*H2 -> 12600 | I16: =200*I2 -> 14200 | ... M16: =200*M2 -> 20600 | N16: =ROUND(SUM(B16:M16),2) -> 138600
A17: Tokens GPT | B17: =10*B2 -> 100 | C17: =10*C2 -> 190 | D17: =10*D2 -> 280 | E17: =10*E2 -> 370 | F17: =10*F2 -> 460 | G17: =10*G2 -> 550 | H17: =10*H2 -> 630 | I17: =10*I2 -> 710 | ... M17: =10*M2 -> 1030 | N17: =ROUND(SUM(B17:M17),2) -> 6930
A18: Telefone | B18: =30*B2 -> 300 | C18: =30*C2 -> 570 | D18: =30*D2 -> 840 | E18: =30*E2 -> 1110 | F18: =30*F2 -> 1380 | G18: =30*G2 -> 1650 | H18: =30*H2 -> 1890 | I18: =30*I2 -> 2130 | ... M18: =30*M2 -> 3090 | N18: =ROUND(SUM(B18:M18),2) -> 20790
A19: Despesas Fixas | B19: =SUM(B20:B40) -> 39748 | C19: =SUM(C20:C40) -> 39780 | D19: =SUM(D20:D40) -> 39780 | E19: =SUM(E20:E40) -> 39780 | F19: =SUM(F20:F40) -> 39780 | G19: =SUM(G20:G40) -> 39780 | H19: =SUM(H20:H40) -> 39780 | I19: =SUM(I20:I40) -> 39780 | ... M19: =SUM(M20:M40) -> 39780 | N19: =ROUND(SUM(B19:M19),2) -> 477328
A20: Pro Labore - CEO | B20: 4440 | C20: 4440 | D20: 4440 | E20: 4440 | F20: 4440 | G20: 4440 | H20: 4440 | I20: 4440 | J20: 4440 | K20: 4440 | L20: 4440 | M20: 4440 | N20: =ROUND(SUM(B20:M20),2) -> 53280
A21: Pro Labore - Operacional | B21: 2220 | C21: 2220 | D21: 2220 | E21: 2220 | F21: 2220 | G21: 2220 | H21: 2220 | I21: 2220 | J21: 2220 | K21: 2220 | L21: 2220 | M21: 2220 | N21: =ROUND(SUM(B21:M21),2) -> 26640
A22: Pro Labore - Operacional | B22: 2220 | C22: 2220 | D22: 2220 | E22: 2220 | F22: 2220 | G22: 2220 | H22: 2220 | I22: 2220 | J22: 2220 | K22: 2220 | L22: 2220 | M22: 2220 | N22: =ROUND(SUM(B22:M22),2) -> 26640
A23: Pro Labore - Operacional | B23: 2220 | C23: 2220 | D23: 2220 | E23: 2220 | F23: 2220 | G23: 2220 | H23: 2220 | I23: 2220 | J23: 2220 | K23: 2220 | L23: 2220 | M23: 2220 | N23: =ROUND(SUM(B23:M23),2) -> 26640
A24: Auxiliar de Serviços Gerais | B24: =Dados!$E$4*Dados!$F$4 -> 1000 | C24: =Dados!$E$4*Dados!$F$4 -> 1000 | D24: =Dados!$E$4*Dados!$F$4 -> 1000 | E24: =Dados!$E$4*Dados!$F$4 -> 1000 | F24: =Dados!$E$4*Dados!$F$4 -> 1000 | G24: =Dados!$E$4*Dados!$F$4 -> 1000 | H24: =Dados!$E$4*Dados!$F$4 -> 1000 | I24: =Dados!$E$4*Dados!$F$4 -> 1000 | ... M24: =Dados!$E$4*Dados!$F$4 -> 1000 | N24: =ROUND(SUM(B24:M24),2) -> 12000
A25: Desenvolvedor | B25: =Dados!$E$5*Dados!$F$5 -> 2000 | C25: =Dados!$E$5*Dados!$F$5 -> 2000 | D25: =Dados!$E$5*Dados!$F$5 -> 2000 | E25: =Dados!$E$5*Dados!$F$5 -> 2000 | F25: =Dados!$E$5*Dados!$F$5 -> 2000 | G25: =Dados!$E$5*Dados!$F$5 -> 2000 | H25: =Dados!$E$5*Dados!$F$5 -> 2000 | I25: =Dados!$E$5*Dados!$F$5 -> 2000 | ... M25: =Dados!$E$5*Dados!$F$5 -> 2000 | N25: =ROUND(SUM(B25:M25),2) -> 24000
A26: Gestor de Tráfego | B26: =Dados!$E$6*Dados!$F$6 -> 2000 | C26: =Dados!$E$6*Dados!$F$6 -> 2000 | D26: =Dados!$E$6*Dados!$F$6 -> 2000 | E26: =Dados!$E$6*Dados!$F$6 -> 2000 | F26: =Dados!$E$6*Dados!$F$6 -> 2000 | G26: =Dados!$E$6*Dados!$F$6 -> 2000 | H26: =Dados!$E$6*Dados!$F$6 -> 2000 | I26: =Dados!$E$6*Dados!$F$6 -> 2000 | ... M26: =Dados!$E$6*Dados!$F$6 -> 2000 | N26: =ROUND(SUM(B26:M26),2) -> 24000
A27: Designer / Editor de Vídeo / Tecnologia | B27: =Dados!$E$7*Dados!$F$7 -> 2000 | C27: =Dados!$E$7*Dados!$F$7 -> 2000 | D27: =Dados!$E$7*Dados!$F$7 -> 2000 | E27: =Dados!$E$7*Dados!$F$7 -> 2000 | F27: =Dados!$E$7*Dados!$F$7 -> 2000 | G27: =Dados!$E$7*Dados!$F$7 -> 2000 | H27: =Dados!$E$7*Dados!$F$7 -> 2000 | I27: =Dados!$E$7*Dados!$F$7 -> 2000 | ... M27: =Dados!$E$7*Dados!$F$7 -> 2000 | N27: =ROUND(SUM(B27:M27),2) -> 24000
A28: Customer Success | B28: =Dados!$E$8*Dados!$F$8 -> 3000 | C28: =Dados!$E$8*Dados!$F$8 -> 3000 | D28: =Dados!$E$8*Dados!$F$8 -> 3000 | E28: =Dados!$E$8*Dados!$F$8 -> 3000 | F28: =Dados!$E$8*Dados!$F$8 -> 3000 | G28: =Dados!$E$8*Dados!$F$8 -> 3000 | H28: =Dados!$E$8*Dados!$F$8 -> 3000 | I28: =Dados!$E$8*Dados!$F$8 -> 3000 | ... M28: =Dados!$E$8*Dados!$F$8 -> 3000 | N28: =ROUND(SUM(B28:M28),2) -> 36000
A29: Vendedores | B29: =Dados!$E$9*Dados!$F$9 -> 0 | C29: 0 | D29: 0 | E29: 0 | F29: 0 | G29: 0 | H29: 0 | I29: 0 | J29: 0 | K29: 0 | L29: 0 | M29: 0 | N29: =ROUND(SUM(B29:M29),2) -> 0
A30: CRM | B30: =Dados!$E$10*Dados!$F$10 -> 300 | C30: 396 | D30: 396 | E30: 396 | F30: 396 | G30: 396 | H30: 396 | I30: 396 | J30: 396 | K30: 396 | L30: 396 | M30: 396 | N30: =ROUND(SUM(B30:M30),2) -> 4656
A31: Internet / Telefonia | B31: 500 | C31: 500 | D31: 500 | E31: 500 | F31: 500 | G31: 500 | H31: 500 | I31: 500 | J31: 500 | K31: 500 | L31: 500 | M31: 500 | N31: =ROUND(SUM(B31:M31),2) -> 6000
A32: Contabilidade | B32: 1000 | C32: 1000 | D32: 1000 | E32: 1000 | F32: 1000 | G32: 1000 | H32: 1000 | I32: 1000 | J32: 1000 | K32: 1000 | L32: 1000 | M32: 1000 | N32: =ROUND(SUM(B32:M32),2) -> 12000
A33: Condominio | B33: 500 | C33: 500 | D33: 500 | E33: 500 | F33: 500 | G33: 500 | H33: 500 | I33: 500 | J33: 500 | K33: 500 | L33: 500 | M33: 500 | N33: =ROUND(SUM(B33:M33),2) -> 6000
A34: Energia Elétrica | B34: 500 | C34: 500 | D34: 500 | E34: 500 | F34: 500 | G34: 500 | H34: 500 | I34: 500 | J34: 500 | K34: 500 | L34: 500 | M34: 500 | N34: =ROUND(SUM(B34:M34),2) -> 6000
A35: Aluguel | B35: 2000 | C35: 2000 | D35: 2000 | E35: 2000 | F35: 2000 | G35: 2000 | H35: 2000 | I35: 2000 | J35: 2000 | K35: 2000 | L35: 2000 | M35: 2000 | N35: =ROUND(SUM(B35:M35),2) -> 24000
A36: Google Workspace | B36: =Dados!$E$11*Dados!$F$11 -> 600 | C36: 686 | D36: 686 | E36: 686 | F36: 686 | G36: 686 | H36: 686 | I36: 686 | J36: 686 | K36: 686 | L36: 686 | M36: 686 | N36: =ROUND(SUM(B36:M36),2) -> 8146
A37: Notion | B37: =Dados!$E$12*Dados!$F$12 -> 1200 | C37: 1050 | D37: 1050 | E37: 1050 | F37: 1050 | G37: 1050 | H37: 1050 | I37: 1050 | J37: 1050 | K37: 1050 | L37: 1050 | M37: 1050 | N37: =ROUND(SUM(B37:M37),2) -> 12750
A38: Treinamentos Udemy | B38: 48 | C38: 48 | D38: 48 | E38: 48 | F38: 48 | G38: 48 | H38: 48 | I38: 48 | J38: 48 | K38: 48 | L38: 48 | M38: 48 | N38: =ROUND(SUM(B38:M38),2) -> 576
A39: Jurídico | B39: 2000 | C39: 2000 | D39: 2000 | E39: 2000 | F39: 2000 | G39: 2000 | H39: 2000 | I39: 2000 | J39: 2000 | K39: 2000 | L39: 2000 | M39: 2000 | N39: =ROUND(SUM(B39:M39),2) -> 24000
A40: Anúncios Online | B40: =Dados!$E$3 -> 10000 | C40: =Dados!$E$3 -> 10000 | D40: =Dados!$E$3 -> 10000 | E40: =Dados!$E$3 -> 10000 | F40: =Dados!$E$3 -> 10000 | G40: =Dados!$E$3 -> 10000 | H40: =Dados!$E$3 -> 10000 | I40: =Dados!$E$3 -> 10000 | ... M40: =Dados!$E$3 -> 10000 | N40: =ROUND(SUM(B40:M40),2) -> 120000
A41: EBITDA = Lucro Líquido | B41: =ROUND(B9-B19,2) -> -35525.78 | C41: =ROUND(C9-C19,2) -> -31757.78 | D41: =ROUND(D9-D19,2) -> -27957.78 | E41: =ROUND(E9-E19,2) -> -24157.79 | F41: =ROUND(F9-F19,2) -> -20357.79 | G41: =ROUND(G9-G19,2) -> -16557.79 | H41: =ROUND(H9-H19,2) -> -13180.01 | I41: =ROUND(I9-I19,2) -> -9802.24 | ... M41: =ROUND(M9-M19,2) -> 3708.87 | N41: =ROUND(SUM(B41:M41),2) -> -184728.15
A42: Margem Líquida % | B42: =B41/B8 -> -5.0601334 | C42: =C41/C8 -> -2.380756 | D42: =D41/D8 -> -1.4222076 | E42: =E41/E8 -> -0.92998046 | F42: =F41/F8 -> -0.63036363 | G42: =G41/G8 -> -0.42880321 | H42: =H41/H8 -> -0.29798441 | I42: =I41/I8 -> -0.1966461 | ... M42: =M41/M8 -> 0.051288823 | N42: =AVERAGE(B42:M42) -> -0.95469448

Sheet 2027
B1: 46388 | C1: 46419 | D1: 46447 | E1: 46478 | F1: 46508 | G1: 46539 | H1: 46569 | I1: 46600 | J1: 46631 | K1: 46661 | L1: 46692 | M1: 46722 | N1: TOTAL
A2: Usuários | B2: =ROUNDDOWN(Dados!$B$1+('2026'!M2-('2026'!M2*Dados!$B$3)),0) -> 110 | C2: =ROUNDDOWN(Dados!$B$1+(B2-(B2*Dados!$B$3)),0) -> 117 | D2: =ROUNDDOWN(Dados!$B$1+(C2-(C2*Dados!$B$3)),0) -> 124 | E2: =ROUNDDOWN(Dados!$B$1+(D2-(D2*Dados!$B$3)),0) -> 131 | F2: =ROUNDDOWN(Dados!$B$1+(E2-(E2*Dados!$B$3)),0) -> 138 | G2: =ROUNDDOWN(Dados!$B$1+(F2-(F2*Dados!$B$3)),0) -> 145 | H2: =ROUNDDOWN(Dados!$B$1+(G2-(G2*Dados!$B$3)),0) -> 152 | I2: =ROUNDDOWN(Dados!$B$1+(H2-(H2*Dados!$B$3)),0) -> 158 | J2: =ROUNDDOWN(Dados!$B$1+(I2-(I2*Dados!$B$3)),0) -> 164 | ... M2: =ROUNDDOWN(Dados!$B$1+(L2-(L2*Dados!$B$3)),0) -> 182 | N2: =M2 -> 182
A4: Receita Total | B4: =ROUND(B5+B6,2) -> 91938 | C4: =ROUND(C5+C6,2) -> 97788.6 | D4: =ROUND(D5+D6,2) -> 103639.2 | E4: =ROUND(E5+E6,2) -> 109489.8 | F4: =ROUND(F5+F6,2) -> 115340.4 | G4: =ROUND(G5+G6,2) -> 121191 | H4: =ROUND(H5+H6,2) -> 127041.6 | I4: =ROUND(I5+I6,2) -> 132056.4 | ... M4: =ROUND(M5+M6,2) -> 152115.6 | N4: =ROUND(SUM(B4:M4),2) -> 1476858.6
A5: Receita Fixa - Mensalidade | B5: =ROUND(B2*Dados!$B$5,0) -> 65670 | C5: =ROUND(C2*Dados!$B$5,0) -> 69849 | D5: =ROUND(D2*Dados!$B$5,0) -> 74028 | E5: =ROUND(E2*Dados!$B$5,0) -> 78207 | F5: =ROUND(F2*Dados!$B$5,0) -> 82386 | G5: =ROUND(G2*Dados!$B$5,0) -> 86565 | H5: =ROUND(H2*Dados!$B$5,0) -> 90744 | I5: =ROUND(I2*Dados!$B$5,0) -> 94326 | ... M5: =ROUND(M2*Dados!$B$5,0) -> 108654 | N5: =ROUND(SUM(B5:M5),2) -> 1054899
A6: Receita Variável - Comissão sobre Vendas Recuperadas | B6: =IF(Dados!$B$9>0,Dados!$B$9*B2,ROUND(B2*(Dados!$B$11*Dados!$B$7),2)) -> 26268 | C6: =IF(Dados!$B$9>0,Dados!$B$9*C2,ROUND(C2*(Dados!$B$11*Dados!$B$7),2)) -> 27939.6 | D6: =IF(Dados!$B$9>0,Dados!$B$9*D2,ROUND(D2*(Dados!$B$11*Dados!$B$7),2)) -> 29611.2 | E6: =IF(Dados!$B$9>0,Dados!$B$9*E2,ROUND(E2*(Dados!$B$11*Dados!$B$7),2)) -> 31282.8 | F6: =IF(Dados!$B$9>0,Dados!$B$9*F2,ROUND(F2*(Dados!$B$11*Dados!$B$7),2)) -> 32954.4 | G6: =IF(Dados!$B$9>0,Dados!$B$9*G2,ROUND(G2*(Dados!$B$11*Dados!$B$7),2)) -> 34626 | H6: =IF(Dados!$B$9>0,Dados!$B$9*H2,ROUND(H2*(Dados!$B$11*Dados!$B$7),2)) -> 36297.6 | I6: =IF(Dados!$B$9>0,Dados!$B$9*I2,ROUND(I2*(Dados!$B$11*Dados!$B$7),2)) -> 37730.4 | ... M6: =IF(Dados!$B$9>0,Dados!$B$9*M2,ROUND(M2*(Dados!$B$11*Dados!$B$7),2)) -> 43461.6 | N6: =ROUND(SUM(B6:M6),2) -> 421959.6
A7: Impostos | B7: =B4*Dados!$E$2 -> 14710.08 | C7: =C4*Dados!$E$2 -> 15646.176 | D7: =D4*Dados!$E$2 -> 16582.272 | E7: =E4*Dados!$E$2 -> 17518.368 | F7: =F4*Dados!$E$2 -> 18454.464 | G7: =G4*Dados!$E$2 -> 19390.56 | H7: =H4*Dados!$E$2 -> 20326.656 | I7: =I4*Dados!$E$2 -> 21129.024 | ... M7: =M4*Dados!$E$2 -> 24338.496 | N7: =ROUND(SUM(B7:M7),2) -> 236297.38
A8: Receita Líquida | B8: =B4-B7 -> 77227.92 | C8: =C4-C7 -> 82142.424 | D8: =D4-D7 -> 87056.928 | E8: =E4-E7 -> 91971.432 | F8: =F4-F7 -> 96885.936 | G8: =G4-G7 -> 101800.44 | H8: =H4-H7 -> 106714.94 | I8: =I4-I7 -> 110927.38 | ... M8: =M4-M7 -> 127777.1 | N8: =ROUND(SUM(B8:M8),2) -> 1240561.2
A9: Receita Bruta | B9: =ROUND(B8-B14-B15-B16-B17-B18,2) -> 46444.42 | C9: =ROUND(C8-C14-C15-C16-C17-C18,2) -> 49399.97 | D9: =ROUND(D8-D14-D15-D16-D17-D18,2) -> 52355.53 | E9: =ROUND(E8-E14-E15-E16-E17-E18,2) -> 55311.08 | F9: =ROUND(F8-F14-F15-F16-F17-F18,2) -> 58266.64 | G9: =ROUND(G8-G14-G15-G16-G17-G18,2) -> 61222.19 | H9: =ROUND(H8-H14-H15-H16-H17-H18,2) -> 64177.74 | I9: =ROUND(I8-I14-I15-I16-I17-I18,2) -> 66711.08 | ... M9: =ROUND(M8-M14-M15-M16-M17-M18,2) -> 76844.4 | N9: =ROUND(SUM(B9:M9),2) -> 746066.27
A10: Margem Bruta % | B10: =IFERROR(ROUND(B9/B4,2),0) -> 0.51 | C10: =IFERROR(ROUND(C9/C4,2),0) -> 0.51 | D10: =IFERROR(ROUND(D9/D4,2),0) -> 0.51 | E10: =IFERROR(ROUND(E9/E4,2),0) -> 0.51 | F10: =IFERROR(ROUND(F9/F4,2),0) -> 0.51 | G10: =IFERROR(ROUND(G9/G4,2),0) -> 0.51 | H10: =IFERROR(ROUND(H9/H4,2),0) -> 0.51 | I10: =IFERROR(ROUND(I9/I4,2),0) -> 0.51 | ... N10: =IFERROR(ROUND(N9/N4,2),0) -> 0.51
A12: Despesa Total | B12: =ROUND(SUM(B13,B19),2) -> 77746.5 | C12: =ROUND(SUM(C13,C19),2) -> 79737.45 | D12: =ROUND(SUM(D13,D19),2) -> 81696.4 | E12: =ROUND(SUM(E13,E19),2) -> 83655.35 | F12: =ROUND(SUM(F13,F19),2) -> 85614.3 | G12: =ROUND(SUM(G13,G19),2) -> 87573.25 | H12: =ROUND(SUM(H13,H19),2) -> 89532.2 | I12: =ROUND(SUM(I13,I19),2) -> 91211.3 | ... M12: =ROUND(SUM(M13,M19),2) -> 97927.7 | N12: =ROUND(SUM(B12:M12),2) -> 1058402.9
A13: Despesas Variáveis | B13: =B14+B15+B16+B17+B18 -> 30783.5 | C13: =C14+C15+C16+C17+C18 -> 32742.45 | D13: =D14+D15+D16+D17+D18 -> 34701.4 | E13: =E14+E15+E16+E17+E18 -> 36660.35 | F13: =F14+F15+F16+F17+F18 -> 38619.3 | G13: =G14+G15+G16+G17+G18 -> 40578.25 | H13: =H14+H15+H16+H17+H18 -> 42537.2 | I13: =I14+I15+I16+I17+I18 -> 44216.3 | ... M13: =M14+M15+M16+M17+M18 -> 50932.7 | N13: =ROUND(SUM(B13:M13),2) -> 494494.95
A14: Taxas de Checkout e Plataformas | B14: =B5*Dados!$E$1 -> 3283.5 | C14: =C5*Dados!$E$1 -> 3492.45 | D14: =D5*Dados!$E$1 -> 3701.4 | E14: =E5*Dados!$E$1 -> 3910.35 | F14: =F5*Dados!$E$1 -> 4119.3 | G14: =G5*Dados!$E$1 -> 4328.25 | H14: =H5*Dados!$E$1 -> 4537.2 | I14: =I5*Dados!$E$1 -> 4716.3 | ... M14: =M5*Dados!$E$1 -> 5432.7 | N14: =ROUND(SUM(B14:M14),2) -> 52744.95
A15: Servidor | B15: =10*B2 -> 1100 | C15: =10*C2 -> 1170 | D15: =10*D2 -> 1240 | E15: =10*E2 -> 1310 | F15: =10*F2 -> 1380 | G15: =10*G2 -> 1450 | H15: =10*H2 -> 1520 | I15: =10*I2 -> 1580 | ... M15: =10*M2 -> 1820 | N15: =ROUND(SUM(B15:M15),2) -> 17670
A16: API Oficial Whatsapp | B16: =200*B2 -> 22000 | C16: =200*C2 -> 23400 | D16: =200*D2 -> 24800 | E16: =200*E2 -> 26200 | F16: =200*F2 -> 27600 | G16: =200*G2 -> 29000 | H16: =200*H2 -> 30400 | I16: =200*I2 -> 31600 | ... M16: =200*M2 -> 36400 | N16: =ROUND(SUM(B16:M16),2) -> 353400
A17: Tokens GPT | B17: =10*B2 -> 1100 | C17: =10*C2 -> 1170 | D17: =10*D2 -> 1240 | E17: =10*E2 -> 1310 | F17: =10*F2 -> 1380 | G17: =10*G2 -> 1450 | H17: =10*H2 -> 1520 | I17: =10*I2 -> 1580 | ... M17: =10*M2 -> 1820 | N17: =ROUND(SUM(B17:M17),2) -> 17670
A18: Telefone | B18: =30*B2 -> 3300 | C18: =30*C2 -> 3510 | D18: =30*D2 -> 3720 | E18: =30*E2 -> 3930 | F18: =30*F2 -> 4140 | G18: =30*G2 -> 4350 | H18: =30*H2 -> 4560 | I18: =30*I2 -> 4740 | ... M18: =30*M2 -> 5460 | N18: =ROUND(SUM(B18:M18),2) -> 53010
A19: Despesas Fixas | B19: =SUM(B20:B40) -> 46963 | C19: =SUM(C20:C40) -> 46995 | D19: =SUM(D20:D40) -> 46995 | E19: =SUM(E20:E40) -> 46995 | F19: =SUM(F20:F40) -> 46995 | G19: =SUM(G20:G40) -> 46995 | H19: =SUM(H20:H40) -> 46995 | I19: =SUM(I20:I40) -> 46995 | ... M19: =SUM(M20:M40) -> 46995 | N19: =ROUND(SUM(B19:M19),2) -> 563908
A20: Pro Labore - CEO | B20: 6660 | C20: 6660 | D20: 6660 | E20: 6660 | F20: 6660 | G20: 6660 | H20: 6660 | I20: 6660 | J20: 6660 | K20: 6660 | L20: 6660 | M20: 6660 | N20: =ROUND(SUM(B20:M20),2) -> 79920
A21: Pro Labore - Operacional | B21: 3885 | C21: 3885 | D21: 3885 | E21: 3885 | F21: 3885 | G21: 3885 | H21: 3885 | I21: 3885 | J21: 3885 | K21: 3885 | L21: 3885 | M21: 3885 | N21: =ROUND(SUM(B21:M21),2) -> 46620
A22: Pro Labore - Operacional | B22: 3885 | C22: 3885 | D22: 3885 | E22: 3885 | F22: 3885 | G22: 3885 | H22: 3885 | I22: 3885 | J22: 3885 | K22: 3885 | L22: 3885 | M22: 3885 | N22: =ROUND(SUM(B22:M22),2) -> 46620
A23: Pro Labore - Operacional | B23: 3885 | C23: 3885 | D23: 3885 | E23: 3885 | F23: 3885 | G23: 3885 | H23: 3885 | I23: 3885 | J23: 3885 | K23: 3885 | L23: 3885 | M23: 3885 | N23: =ROUND(SUM(B23:M23),2) -> 46620
A24: Auxiliar de Serviços Gerais | B24: =Dados!$E$4*Dados!$F$4 -> 1000 | C24: =Dados!$E$4*Dados!$F$4 -> 1000 | D24: =Dados!$E$4*Dados!$F$4 -> 1000 | E24: =Dados!$E$4*Dados!$F$4 -> 1000 | F24: =Dados!$E$4*Dados!$F$4 -> 1000 | G24: =Dados!$E$4*Dados!$F$4 -> 1000 | H24: =Dados!$E$4*Dados!$F$4 -> 1000 | I24: =Dados!$E$4*Dados!$F$4 -> 1000 | ... M24: =Dados!$E$4*Dados!$F$4 -> 1000 | N24: =ROUND(SUM(B24:M24),2) -> 12000
A25: Desenvolvedor | B25: =Dados!$E$5*Dados!$F$5 -> 2000 | C25: =Dados!$E$5*Dados!$F$5 -> 2000 | D25: =Dados!$E$5*Dados!$F$5 -> 2000 | E25: =Dados!$E$5*Dados!$F$5 -> 2000 | F25: =Dados!$E$5*Dados!$F$5 -> 2000 | G25: =Dados!$E$5*Dados!$F$5 -> 2000 | H25: =Dados!$E$5*Dados!$F$5 -> 2000 | I25: =Dados!$E$5*Dados!$F$5 -> 2000 | ... M25: =Dados!$E$5*Dados!$F$5 -> 2000 | N25: =ROUND(SUM(B25:M25),2) -> 24000
A26: Gestor de Tráfego | B26: =Dados!$E$6*Dados!$F$6 -> 2000 | C26: =Dados!$E$6*Dados!$F$6 -> 2000 | D26: =Dados!$E$6*Dados!$F$6 -> 2000 | E26: =Dados!$E$6*Dados!$F$6 -> 2000 | F26: =Dados!$E$6*Dados!$F$6 -> 2000 | G26: =Dados!$E$6*Dados!$F$6 -> 2000 | H26: =Dados!$E$6*Dados!$F$6 -> 2000 | I26: =Dados!$E$6*Dados!$F$6 -> 2000 | ... M26: =Dados!$E$6*Dados!$F$6 -> 2000 | N26: =ROUND(SUM(B26:M26),2) -> 24000
A27: Designer / Editor de Vídeo / Tecnologia | B27: =Dados!$E$7*Dados!$F$7 -> 2000 | C27: =Dados!$E$7*Dados!$F$7 -> 2000 | D27: =Dados!$E$7*Dados!$F$7 -> 2000 | E27: =Dados!$E$7*Dados!$F$7 -> 2000 | F27: =Dados!$E$7*Dados!$F$7 -> 2000 | G27: =Dados!$E$7*Dados!$F$7 -> 2000 | H27: =Dados!$E$7*Dados!$F$7 -> 2000 | I27: =Dados!$E$7*Dados!$F$7 -> 2000 | ... M27: =Dados!$E$7*Dados!$F$7 -> 2000 | N27: =ROUND(SUM(B27:M27),2) -> 24000
A28: Customer Success | B28: =Dados!$E$8*Dados!$F$8 -> 3000 | C28: =Dados!$E$8*Dados!$F$8 -> 3000 | D28: =Dados!$E$8*Dados!$F$8 -> 3000 | E28: =Dados!$E$8*Dados!$F$8 -> 3000 | F28: =Dados!$E$8*Dados!$F$8 -> 3000 | G28: =Dados!$E$8*Dados!$F$8 -> 3000 | H28: =Dados!$E$8*Dados!$F$8 -> 3000 | I28: =Dados!$E$8*Dados!$F$8 -> 3000 | ... M28: =Dados!$E$8*Dados!$F$8 -> 3000 | N28: =ROUND(SUM(B28:M28),2) -> 36000
A29: Vendedores | B29: =Dados!$E$9*Dados!$F$9 -> 0 | C29: 0 | D29: 0 | E29: 0 | F29: 0 | G29: 0 | H29: 0 | I29: 0 | J29: 0 | K29: 0 | L29: 0 | M29: 0 | N29: =ROUND(SUM(B29:M29),2) -> 0
A30: CRM | B30: =Dados!$E$10*Dados!$F$10 -> 300 | C30: 396 | D30: 396 | E30: 396 | F30: 396 | G30: 396 | H30: 396 | I30: 396 | J30: 396 | K30: 396 | L30: 396 | M30: 396 | N30: =ROUND(SUM(B30:M30),2) -> 4656
A31: Internet / Telefonia | B31: 500 | C31: 500 | D31: 500 | E31: 500 | F31: 500 | G31: 500 | H31: 500 | I31: 500 | J31: 500 | K31: 500 | L31: 500 | M31: 500 | N31: =ROUND(SUM(B31:M31),2) -> 6000
A32: Contabilidade | B32: 1000 | C32: 1000 | D32: 1000 | E32: 1000 | F32: 1000 | G32: 1000 | H32: 1000 | I32: 1000 | J32: 1000 | K32: 1000 | L32: 1000 | M32: 1000 | N32: =ROUND(SUM(B32:M32),2) -> 12000
A33: Condominio | B33: 500 | C33: 500 | D33: 500 | E33: 500 | F33: 500 | G33: 500 | H33: 500 | I33: 500 | J33: 500 | K33: 500 | L33: 500 | M33: 500 | N33: =ROUND(SUM(B33:M33),2) -> 6000
A34: Energia Elétrica | B34: 500 | C34: 500 | D34: 500 | E34: 500 | F34: 500 | G34: 500 | H34: 500 | I34: 500 | J34: 500 | K34: 500 | L34: 500 | M34: 500 | N34: =ROUND(SUM(B34:M34),2) -> 6000
A35: Aluguel | B35: 2000 | C35: 2000 | D35: 2000 | E35: 2000 | F35: 2000 | G35: 2000 | H35: 2000 | I35: 2000 | J35: 2000 | K35: 2000 | L35: 2000 | M35: 2000 | N35: =ROUND(SUM(B35:M35),2) -> 24000
A36: Google Workspace | B36: =Dados!$E$11*Dados!$F$11 -> 600 | C36: 686 | D36: 686 | E36: 686 | F36: 686 | G36: 686 | H36: 686 | I36: 686 | J36: 686 | K36: 686 | L36: 686 | M36: 686 | N36: =ROUND(SUM(B36:M36),2) -> 8146
A37: Notion | B37: =Dados!$E$12*Dados!$F$12 -> 1200 | C37: 1050 | D37: 1050 | E37: 1050 | F37: 1050 | G37: 1050 | H37: 1050 | I37: 1050 | J37: 1050 | K37: 1050 | L37: 1050 | M37: 1050 | N37: =ROUND(SUM(B37:M37),2) -> 12750
A38: Treinamentos Udemy | B38: 48 | C38: 48 | D38: 48 | E38: 48 | F38: 48 | G38: 48 | H38: 48 | I38: 48 | J38: 48 | K38: 48 | L38: 48 | M38: 48 | N38: =ROUND(SUM(B38:M38),2) -> 576
A39: Jurídico | B39: 2000 | C39: 2000 | D39: 2000 | E39: 2000 | F39: 2000 | G39: 2000 | H39: 2000 | I39: 2000 | J39: 2000 | K39: 2000 | L39: 2000 | M39: 2000 | N39: =ROUND(SUM(B39:M39),2) -> 24000
A40: Anúncios Online | B40: =Dados!$E$3 -> 10000 | C40: =Dados!$E$3 -> 10000 | D40: =Dados!$E$3 -> 10000 | E40: =Dados!$E$3 -> 10000 | F40: =Dados!$E$3 -> 10000 | G40: =Dados!$E$3 -> 10000 | H40: =Dados!$E$3 -> 10000 | I40: =Dados!$E$3 -> 10000 | ... M40: =Dados!$E$3 -> 10000 | N40: =ROUND(SUM(B40:M40),2) -> 120000
A41: EBITDA = Lucro Líquido | B41: =ROUND(B9-B19,2) -> -518.58 | C41: =ROUND(C9-C19,2) -> 2404.97 | D41: =ROUND(D9-D19,2) -> 5360.53 | E41: =ROUND(E9-E19,2) -> 8316.08 | F41: =ROUND(F9-F19,2) -> 11271.64 | G41: =ROUND(G9-G19,2) -> 14227.19 | H41: =ROUND(H9-H19,2) -> 17182.74 | I41: =ROUND(I9-I19,2) -> 19716.08 | ... M41: =ROUND(M9-M19,2) -> 29849.4 | N41: =ROUND(SUM(B41:M41),2) -> 182158.27
A42: Margem Líquida % | B42: =B41/B8 -> -0.006714929 | C42: =C41/C8 -> 0.02927805 | D42: =D41/D8 -> 0.061574996 | E42: =E41/E8 -> 0.090420251 | F42: =F41/F8 -> 0.11633928 | G42: =G41/G8 -> 0.13975568 | H42: =H41/H8 -> 0.16101531 | I42: =I41/I8 -> 0.17773863 | ... M42: =M41/M8 -> 0.23360523 | N42: =AVERAGE(B42:M42) -> 0.13541345

Sheet 2028
B1: 46753 | C1: 46784 | D1: 46813 | E1: 46844 | F1: 46874 | G1: 46905 | H1: 46935 | I1: 46966 | J1: 46997 | K1: 47027 | L1: 47058 | M1: 47088 | N1: TOTAL
A2: Usuários | B2: =ROUNDDOWN(Dados!$B$1+('2027'!M2-('2027'!M2*Dados!$B$3)),0) -> 188 | C2: =ROUNDDOWN(Dados!$B$1+(B2-(B2*Dados!$B$3)),0) -> 194 | D2: =ROUNDDOWN(Dados!$B$1+(C2-(C2*Dados!$B$3)),0) -> 200 | E2: =ROUNDDOWN(Dados!$B$1+(D2-(D2*Dados!$B$3)),0) -> 206 | F2: =ROUNDDOWN(Dados!$B$1+(E2-(E2*Dados!$B$3)),0) -> 211 | G2: =ROUNDDOWN(Dados!$B$1+(F2-(F2*Dados!$B$3)),0) -> 216 | H2: =ROUNDDOWN(Dados!$B$1+(G2-(G2*Dados!$B$3)),0) -> 221 | I2: =ROUNDDOWN(Dados!$B$1+(H2-(H2*Dados!$B$3)),0) -> 226 | J2: =ROUNDDOWN(Dados!$B$1+(I2-(I2*Dados!$B$3)),0) -> 231 | ... M2: =ROUNDDOWN(Dados!$B$1+(L2-(L2*Dados!$B$3)),0) -> 246 | N2: =M2 -> 246
A4: Receita Total | B4: =ROUND(B5+B6,2) -> 157130.4 | C4: =ROUND(C5+C6,2) -> 162145.2 | D4: =ROUND(D5+D6,2) -> 167160 | E4: =ROUND(E5+E6,2) -> 172174.8 | F4: =ROUND(F5+F6,2) -> 176353.8 | G4: =ROUND(G5+G6,2) -> 180532.8 | H4: =ROUND(H5+H6,2) -> 184711.8 | I4: =ROUND(I5+I6,2) -> 188890.8 | ... M4: =ROUND(M5+M6,2) -> 205606.8 | N4: =ROUND(SUM(B4:M4),2) -> 2186452.8
A5: Receita Fixa - Mensalidade | B5: =ROUND(B2*Dados!$B$5,0) -> 112236 | C5: =ROUND(C2*Dados!$B$5,0) -> 115818 | D5: =ROUND(D2*Dados!$B$5,0) -> 119400 | E5: =ROUND(E2*Dados!$B$5,0) -> 122982 | F5: =ROUND(F2*Dados!$B$5,0) -> 125967 | G5: =ROUND(G2*Dados!$B$5,0) -> 128952 | H5: =ROUND(H2*Dados!$B$5,0) -> 131937 | I5: =ROUND(I2*Dados!$B$5,0) -> 134922 | ... M5: =ROUND(M2*Dados!$B$5,0) -> 146862 | N5: =ROUND(SUM(B5:M5),2) -> 1561752
A6: Receita Variável - Comissão sobre Vendas Recuperadas | B6: =IF(Dados!$B$9>0,Dados!$B$9*B2,ROUND(B2*(Dados!$B$11*Dados!$B$7),2)) -> 44894.4 | C6: =IF(Dados!$B$9>0,Dados!$B$9*C2,ROUND(C2*(Dados!$B$11*Dados!$B$7),2)) -> 46327.2 | D6: =IF(Dados!$B$9>0,Dados!$B$9*D2,ROUND(D2*(Dados!$B$11*Dados!$B$7),2)) -> 47760 | E6: =IF(Dados!$B$9>0,Dados!$B$9*E2,ROUND(E2*(Dados!$B$11*Dados!$B$7),2)) -> 49192.8 | F6: =IF(Dados!$B$9>0,Dados!$B$9*F2,ROUND(F2*(Dados!$B$11*Dados!$B$7),2)) -> 50386.8 | G6: =IF(Dados!$B$9>0,Dados!$B$9*G2,ROUND(G2*(Dados!$B$11*Dados!$B$7),2)) -> 51580.8 | H6: =IF(Dados!$B$9>0,Dados!$B$9*H2,ROUND(H2*(Dados!$B$11*Dados!$B$7),2)) -> 52774.8 | I6: =IF(Dados!$B$9>0,Dados!$B$9*I2,ROUND(I2*(Dados!$B$11*Dados!$B$7),2)) -> 53968.8 | ... M6: =IF(Dados!$B$9>0,Dados!$B$9*M2,ROUND(M2*(Dados!$B$11*Dados!$B$7),2)) -> 58744.8 | N6: =ROUND(SUM(B6:M6),2) -> 624700.8
A7: Impostos | B7: =B4*Dados!$E$2 -> 25140.864 | C7: =C4*Dados!$E$2 -> 25943.232 | D7: =D4*Dados!$E$2 -> 26745.6 | E7: =E4*Dados!$E$2 -> 27547.968 | F7: =F4*Dados!$E$2 -> 28216.608 | G7: =G4*Dados!$E$2 -> 28885.248 | H7: =H4*Dados!$E$2 -> 29553.888 | I7: =I4*Dados!$E$2 -> 30222.528 | ... M7: =M4*Dados!$E$2 -> 32897.088 | N7: =ROUND(SUM(B7:M7),2) -> 349832.45
A8: Receita Líquida | B8: =B4-B7 -> 131989.54 | C8: =C4-C7 -> 136201.97 | D8: =D4-D7 -> 140414.4 | E8: =E4-E7 -> 144626.83 | F8: =F4-F7 -> 148137.19 | G8: =G4-G7 -> 151647.55 | H8: =H4-H7 -> 155157.91 | I8: =I4-I7 -> 158668.27 | ... M8: =M4-M7 -> 172709.71 | N8: =ROUND(SUM(B8:M8),2) -> 1836620.4
A9: Receita Bruta | B9: =ROUND(B8-B14-B15-B16-B17-B18,2) -> 79377.74 | C9: =ROUND(C8-C14-C15-C16-C17-C18,2) -> 81911.07 | D9: =ROUND(D8-D14-D15-D16-D17-D18,2) -> 84444.4 | E9: =ROUND(E8-E14-E15-E16-E17-E18,2) -> 86977.73 | F9: =ROUND(F8-F14-F15-F16-F17-F18,2) -> 89088.84 | G9: =ROUND(G8-G14-G15-G16-G17-G18,2) -> 91199.95 | H9: =ROUND(H8-H14-H15-H16-H17-H18,2) -> 93311.06 | I9: =ROUND(I8-I14-I15-I16-I17-I18,2) -> 95422.17 | ... M9: =ROUND(M8-M14-M15-M16-M17-M18,2) -> 103866.61 | N9: =ROUND(SUM(B9:M9),2) -> 1104532.7
A10: Margem Bruta % | B10: =IFERROR(ROUND(B9/B4,2),0) -> 0.51 | C10: =IFERROR(ROUND(C9/C4,2),0) -> 0.51 | D10: =IFERROR(ROUND(D9/D4,2),0) -> 0.51 | E10: =IFERROR(ROUND(E9/E4,2),0) -> 0.51 | F10: =IFERROR(ROUND(F9/F4,2),0) -> 0.51 | G10: =IFERROR(ROUND(G9/G4,2),0) -> 0.51 | H10: =IFERROR(ROUND(H9/H4,2),0) -> 0.51 | I10: =IFERROR(ROUND(I9/I4,2),0) -> 0.51 | ... N10: =IFERROR(ROUND(N9/N4,2),0) -> 0.51
A12: Despesa Total | B12: =ROUND(SUM(B13,B19),2) -> 106789.8 | C12: =ROUND(SUM(C13,C19),2) -> 108468.9 | D12: =ROUND(SUM(D13,D19),2) -> 110148 | E12: =ROUND(SUM(E13,E19),2) -> 111827.1 | F12: =ROUND(SUM(F13,F19),2) -> 113226.35 | G12: =ROUND(SUM(G13,G19),2) -> 114625.6 | H12: =ROUND(SUM(H13,H19),2) -> 116024.85 | I12: =ROUND(SUM(I13,I19),2) -> 117424.1 | ... M12: =ROUND(SUM(M13,M19),2) -> 123021.1 | N12: =ROUND(SUM(B12:M12),2) -> 1382223.6
A13: Despesas Variáveis | B13: =B14+B15+B16+B17+B18 -> 52611.8 | C13: =C14+C15+C16+C17+C18 -> 54290.9 | D13: =D14+D15+D16+D17+D18 -> 55970 | E13: =E14+E15+E16+E17+E18 -> 57649.1 | F13: =F14+F15+F16+F17+F18 -> 59048.35 | G13: =G14+G15+G16+G17+G18 -> 60447.6 | H13: =H14+H15+H16+H17+H18 -> 61846.85 | I13: =I14+I15+I16+I17+I18 -> 63246.1 | ... M13: =M14+M15+M16+M17+M18 -> 68843.1 | N13: =ROUND(SUM(B13:M13),2) -> 732087.6
A14: Taxas de Checkout e Plataformas | B14: =B5*Dados!$E$1 -> 5611.8 | C14: =C5*Dados!$E$1 -> 5790.9 | D14: =D5*Dados!$E$1 -> 5970 | E14: =E5*Dados!$E$1 -> 6149.1 | F14: =F5*Dados!$E$1 -> 6298.35 | G14: =G5*Dados!$E$1 -> 6447.6 | H14: =H5*Dados!$E$1 -> 6596.85 | I14: =I5*Dados!$E$1 -> 6746.1 | ... M14: =M5*Dados!$E$1 -> 7343.1 | N14: =ROUND(SUM(B14:M14),2) -> 78087.6
A15: Servidor | B15: =10*B2 -> 1880 | C15: =10*C2 -> 1940 | D15: =10*D2 -> 2000 | E15: =10*E2 -> 2060 | F15: =10*F2 -> 2110 | G15: =10*G2 -> 2160 | H15: =10*H2 -> 2210 | I15: =10*I2 -> 2260 | ... M15: =10*M2 -> 2460 | N15: =ROUND(SUM(B15:M15),2) -> 26160
A16: API Oficial Whatsapp | B16: =200*B2 -> 37600 | C16: =200*C2 -> 38800 | D16: =200*D2 -> 40000 | E16: =200*E2 -> 41200 | F16: =200*F2 -> 42200 | G16: =200*G2 -> 43200 | H16: =200*H2 -> 44200 | I16: =200*I2 -> 45200 | ... M16: =200*M2 -> 49200 | N16: =ROUND(SUM(B16:M16),2) -> 523200
A17: Tokens GPT | B17: =10*B2 -> 1880 | C17: =10*C2 -> 1940 | D17: =10*D2 -> 2000 | E17: =10*E2 -> 2060 | F17: =10*F2 -> 2110 | G17: =10*G2 -> 2160 | H17: =10*H2 -> 2210 | I17: =10*I2 -> 2260 | ... M17: =10*M2 -> 2460 | N17: =ROUND(SUM(B17:M17),2) -> 26160
A18: Telefone | B18: =30*B2 -> 5640 | C18: =30*C2 -> 5820 | D18: =30*D2 -> 6000 | E18: =30*E2 -> 6180 | F18: =30*F2 -> 6330 | G18: =30*G2 -> 6480 | H18: =30*H2 -> 6630 | I18: =30*I2 -> 6780 | ... M18: =30*M2 -> 7380 | N18: =ROUND(SUM(B18:M18),2) -> 78480
A19: Despesas Fixas | B19: =SUM(B20:B40) -> 54178 | C19: =SUM(C20:C40) -> 54178 | D19: =SUM(D20:D40) -> 54178 | E19: =SUM(E20:E40) -> 54178 | F19: =SUM(F20:F40) -> 54178 | G19: =SUM(G20:G40) -> 54178 | H19: =SUM(H20:H40) -> 54178 | I19: =SUM(I20:I40) -> 54178 | ... M19: =SUM(M20:M40) -> 54178 | N19: =ROUND(SUM(B19:M19),2) -> 650136
A20: Pro Labore - CEO | B20: 8880 | C20: 8880 | D20: 8880 | E20: 8880 | F20: 8880 | G20: 8880 | H20: 8880 | I20: 8880 | J20: 8880 | K20: 8880 | L20: 8880 | M20: 8880 | N20: =ROUND(SUM(B20:M20),2) -> 106560
A21: Pro Labore - Operacional | B21: 5550 | C21: 5550 | D21: 5550 | E21: 5550 | F21: 5550 | G21: 5550 | H21: 5550 | I21: 5550 | J21: 5550 | K21: 5550 | L21: 5550 | M21: 5550 | N21: =ROUND(SUM(B21:M21),2) -> 66600
A22: Pro Labore - Operacional | B22: 5550 | C22: 5550 | D22: 5550 | E22: 5550 | F22: 5550 | G22: 5550 | H22: 5550 | I22: 5550 | J22: 5550 | K22: 5550 | L22: 5550 | M22: 5550 | N22: =ROUND(SUM(B22:M22),2) -> 66600
A23: Pro Labore - Operacional | B23: 5550 | C23: 5550 | D23: 5550 | E23: 5550 | F23: 5550 | G23: 5550 | H23: 5550 | I23: 5550 | J23: 5550 | K23: 5550 | L23: 5550 | M23: 5550 | N23: =ROUND(SUM(B23:M23),2) -> 66600
A24: Auxiliar de Serviços Gerais | B24: =Dados!$E$4*Dados!$F$4 -> 1000 | C24: =Dados!$E$4*Dados!$F$4 -> 1000 | D24: =Dados!$E$4*Dados!$F$4 -> 1000 | E24: =Dados!$E$4*Dados!$F$4 -> 1000 | F24: =Dados!$E$4*Dados!$F$4 -> 1000 | G24: =Dados!$E$4*Dados!$F$4 -> 1000 | H24: =Dados!$E$4*Dados!$F$4 -> 1000 | I24: =Dados!$E$4*Dados!$F$4 -> 1000 | ... M24: =Dados!$E$4*Dados!$F$4 -> 1000 | N24: =ROUND(SUM(B24:M24),2) -> 12000
A25: Desenvolvedor | B25: =Dados!$E$5*Dados!$F$5 -> 2000 | C25: =Dados!$E$5*Dados!$F$5 -> 2000 | D25: =Dados!$E$5*Dados!$F$5 -> 2000 | E25: =Dados!$E$5*Dados!$F$5 -> 2000 | F25: =Dados!$E$5*Dados!$F$5 -> 2000 | G25: =Dados!$E$5*Dados!$F$5 -> 2000 | H25: =Dados!$E$5*Dados!$F$5 -> 2000 | I25: =Dados!$E$5*Dados!$F$5 -> 2000 | ... M25: =Dados!$E$5*Dados!$F$5 -> 2000 | N25: =ROUND(SUM(B25:M25),2) -> 24000
A26: Gestor de Tráfego | B26: =Dados!$E$6*Dados!$F$6 -> 2000 | C26: =Dados!$E$6*Dados!$F$6 -> 2000 | D26: =Dados!$E$6*Dados!$F$6 -> 2000 | E26: =Dados!$E$6*Dados!$F$6 -> 2000 | F26: =Dados!$E$6*Dados!$F$6 -> 2000 | G26: =Dados!$E$6*Dados!$F$6 -> 2000 | H26: =Dados!$E$6*Dados!$F$6 -> 2000 | I26: =Dados!$E$6*Dados!$F$6 -> 2000 | ... M26: =Dados!$E$6*Dados!$F$6 -> 2000 | N26: =ROUND(SUM(B26:M26),2) -> 24000
A27: Designer / Editor de Vídeo / Tecnologia | B27: =Dados!$E$7*Dados!$F$7 -> 2000 | C27: =Dados!$E$7*Dados!$F$7 -> 2000 | D27: =Dados!$E$7*Dados!$F$7 -> 2000 | E27: =Dados!$E$7*Dados!$F$7 -> 2000 | F27: =Dados!$E$7*Dados!$F$7 -> 2000 | G27: =Dados!$E$7*Dados!$F$7 -> 2000 | H27: =Dados!$E$7*Dados!$F$7 -> 2000 | I27: =Dados!$E$7*Dados!$F$7 -> 2000 | ... M27: =Dados!$E$7*Dados!$F$7 -> 2000 | N27: =ROUND(SUM(B27:M27),2) -> 24000
A28: Customer Success | B28: =Dados!$E$8*Dados!$F$8 -> 3000 | C28: =Dados!$E$8*Dados!$F$8 -> 3000 | D28: =Dados!$E$8*Dados!$F$8 -> 3000 | E28: =Dados!$E$8*Dados!$F$8 -> 3000 | F28: =Dados!$E$8*Dados!$F$8 -> 3000 | G28: =Dados!$E$8*Dados!$F$8 -> 3000 | H28: =Dados!$E$8*Dados!$F$8 -> 3000 | I28: =Dados!$E$8*Dados!$F$8 -> 3000 | ... M28: =Dados!$E$8*Dados!$F$8 -> 3000 | N28: =ROUND(SUM(B28:M28),2) -> 36000
A29: Vendedores | B29: =Dados!$E$9*Dados!$F$9 -> 0 | C29: =Dados!$E$9*Dados!$F$9 -> 0 | D29: =Dados!$E$9*Dados!$F$9 -> 0 | E29: =Dados!$E$9*Dados!$F$9 -> 0 | F29: =Dados!$E$9*Dados!$F$9 -> 0 | G29: =Dados!$E$9*Dados!$F$9 -> 0 | H29: =Dados!$E$9*Dados!$F$9 -> 0 | I29: =Dados!$E$9*Dados!$F$9 -> 0 | ... M29: =Dados!$E$9*Dados!$F$9 -> 0 | N29: =ROUND(SUM(B29:M29),2) -> 0
A30: CRM | B30: =Dados!$E$10*Dados!$F$10 -> 300 | C30: =Dados!$E$10*Dados!$F$10 -> 300 | D30: =Dados!$E$10*Dados!$F$10 -> 300 | E30: =Dados!$E$10*Dados!$F$10 -> 300 | F30: =Dados!$E$10*Dados!$F$10 -> 300 | G30: =Dados!$E$10*Dados!$F$10 -> 300 | H30: =Dados!$E$10*Dados!$F$10 -> 300 | I30: =Dados!$E$10*Dados!$F$10 -> 300 | ... M30: =Dados!$E$10*Dados!$F$10 -> 300 | N30: =ROUND(SUM(B30:M30),2) -> 3600
A31: Internet / Telefonia | B31: 500 | C31: 500 | D31: 500 | E31: 500 | F31: 500 | G31: 500 | H31: 500 | I31: 500 | J31: 500 | K31: 500 | L31: 500 | M31: 500 | N31: =ROUND(SUM(B31:M31),2) -> 6000
A32: Contabilidade | B32: 1000 | C32: 1000 | D32: 1000 | E32: 1000 | F32: 1000 | G32: 1000 | H32: 1000 | I32: 1000 | J32: 1000 | K32: 1000 | L32: 1000 | M32: 1000 | N32: =ROUND(SUM(B32:M32),2) -> 12000
A33: Condominio | B33: 500 | C33: 500 | D33: 500 | E33: 500 | F33: 500 | G33: 500 | H33: 500 | I33: 500 | J33: 500 | K33: 500 | L33: 500 | M33: 500 | N33: =ROUND(SUM(B33:M33),2) -> 6000
A34: Energia Elétrica | B34: 500 | C34: 500 | D34: 500 | E34: 500 | F34: 500 | G34: 500 | H34: 500 | I34: 500 | J34: 500 | K34: 500 | L34: 500 | M34: 500 | N34: =ROUND(SUM(B34:M34),2) -> 6000
A35: Aluguel | B35: 2000 | C35: 2000 | D35: 2000 | E35: 2000 | F35: 2000 | G35: 2000 | H35: 2000 | I35: 2000 | J35: 2000 | K35: 2000 | L35: 2000 | M35: 2000 | N35: =ROUND(SUM(B35:M35),2) -> 24000
A36: Google Workspace | B36: =Dados!$E$11*Dados!$F$11 -> 600 | C36: =Dados!$E$11*Dados!$F$11 -> 600 | D36: =Dados!$E$11*Dados!$F$11 -> 600 | E36: =Dados!$E$11*Dados!$F$11 -> 600 | F36: =Dados!$E$11*Dados!$F$11 -> 600 | G36: =Dados!$E$11*Dados!$F$11 -> 600 | H36: =Dados!$E$11*Dados!$F$11 -> 600 | I36: =Dados!$E$11*Dados!$F$11 -> 600 | ... M36: =Dados!$E$11*Dados!$F$11 -> 600 | N36: =ROUND(SUM(B36:M36),2) -> 7200
A37: Notion | B37: =Dados!$E$12*Dados!$F$12 -> 1200 | C37: =Dados!$E$12*Dados!$F$12 -> 1200 | D37: =Dados!$E$12*Dados!$F$12 -> 1200 | E37: =Dados!$E$12*Dados!$F$12 -> 1200 | F37: =Dados!$E$12*Dados!$F$12 -> 1200 | G37: =Dados!$E$12*Dados!$F$12 -> 1200 | H37: =Dados!$E$12*Dados!$F$12 -> 1200 | I37: =Dados!$E$12*Dados!$F$12 -> 1200 | ... M37: =Dados!$E$12*Dados!$F$12 -> 1200 | N37: =ROUND(SUM(B37:M37),2) -> 14400
A38: Treinamentos Udemy | B38: 48 | C38: 48 | D38: 48 | E38: 48 | F38: 48 | G38: 48 | H38: 48 | I38: 48 | J38: 48 | K38: 48 | L38: 48 | M38: 48 | N38: =ROUND(SUM(B38:M38),2) -> 576
A39: Jurídico | B39: 2000 | C39: 2000 | D39: 2000 | E39: 2000 | F39: 2000 | G39: 2000 | H39: 2000 | I39: 2000 | J39: 2000 | K39: 2000 | L39: 2000 | M39: 2000 | N39: =ROUND(SUM(B39:M39),2) -> 24000
A40: Anúncios Online | B40: =Dados!$E$3 -> 10000 | C40: =Dados!$E$3 -> 10000 | D40: =Dados!$E$3 -> 10000 | E40: =Dados!$E$3 -> 10000 | F40: =Dados!$E$3 -> 10000 | G40: =Dados!$E$3 -> 10000 | H40: =Dados!$E$3 -> 10000 | I40: =Dados!$E$3 -> 10000 | ... M40: =Dados!$E$3 -> 10000 | N40: =ROUND(SUM(B40:M40),2) -> 120000
A41: EBITDA = Lucro Líquido | B41: =ROUND(B9-B19,2) -> 25199.74 | C41: =ROUND(C9-C19,2) -> 27733.07 | D41: =ROUND(D9-D19,2) -> 30266.4 | E41: =ROUND(E9-E19,2) -> 32799.73 | F41: =ROUND(F9-F19,2) -> 34910.84 | G41: =ROUND(G9-G19,2) -> 37021.95 | H41: =ROUND(H9-H19,2) -> 39133.06 | I41: =ROUND(I9-I19,2) -> 41244.17 | ... M41: =ROUND(M9-M19,2) -> 49688.61 | N41: =ROUND(SUM(B41:M41),2) -> 454396.74
A42: Margem Líquida % | B42: =B41/B8 -> 0.19092226 | C42: =C41/C8 -> 0.20361725 | D42: =D41/D8 -> 0.21555054 | E42: =E41/E8 -> 0.22678869 | F42: =F41/F8 -> 0.2356656 | G42: =G41/G8 -> 0.24413154 | H42: =H41/H8 -> 0.2522144 | I42: =I41/I8 -> 0.25993962 | ... M42: =M41/M8 -> 0.28770015 | N42: =AVERAGE(B42:M42) -> 0.24495504

Sheet 2029
B1: 47119 | C1: 47150 | D1: 47178 | E1: 47209 | F1: 47239 | G1: 47270 | H1: 47300 | I1: 47331 | J1: 47362 | K1: 47392 | L1: 47423 | M1: 47453 | N1: TOTAL
A2: Usuários | B2: =ROUNDDOWN(Dados!$B$1+('2028'!M2-('2028'!M2*Dados!$B$3)),0) -> 251 | C2: =ROUNDDOWN(Dados!$B$1+(B2-(B2*Dados!$B$3)),0) -> 255 | D2: =ROUNDDOWN(Dados!$B$1+(C2-(C2*Dados!$B$3)),0) -> 259 | E2: =ROUNDDOWN(Dados!$B$1+(D2-(D2*Dados!$B$3)),0) -> 263 | F2: =ROUNDDOWN(Dados!$B$1+(E2-(E2*Dados!$B$3)),0) -> 267 | G2: =ROUNDDOWN(Dados!$B$1+(F2-(F2*Dados!$B$3)),0) -> 271 | H2: =ROUNDDOWN(Dados!$B$1+(G2-(G2*Dados!$B$3)),0) -> 275 | I2: =ROUNDDOWN(Dados!$B$1+(H2-(H2*Dados!$B$3)),0) -> 279 | J2: =ROUNDDOWN(Dados!$B$1+(I2-(I2*Dados!$B$3)),0) -> 283 | ... M2: =ROUNDDOWN(Dados!$B$1+(L2-(L2*Dados!$B$3)),0) -> 295 | N2: =M2 -> 295
A4: Receita Total | B4: =ROUND(B5+B6,2) -> 209785.8 | C4: =ROUND(C5+C6,2) -> 213129 | D4: =ROUND(D5+D6,2) -> 216472.2 | E4: =ROUND(E5+E6,2) -> 219815.4 | F4: =ROUND(F5+F6,2) -> 223158.6 | G4: =ROUND(G5+G6,2) -> 226501.8 | H4: =ROUND(H5+H6,2) -> 229845 | I4: =ROUND(I5+I6,2) -> 233188.2 | ... M4: =ROUND(M5+M6,2) -> 246561 | N4: =ROUND(SUM(B4:M4),2) -> 2738080.8
A5: Receita Fixa - Mensalidade | B5: =ROUND(B2*Dados!$B$5,0) -> 149847 | C5: =ROUND(C2*Dados!$B$5,0) -> 152235 | D5: =ROUND(D2*Dados!$B$5,0) -> 154623 | E5: =ROUND(E2*Dados!$B$5,0) -> 157011 | F5: =ROUND(F2*Dados!$B$5,0) -> 159399 | G5: =ROUND(G2*Dados!$B$5,0) -> 161787 | H5: =ROUND(H2*Dados!$B$5,0) -> 164175 | I5: =ROUND(I2*Dados!$B$5,0) -> 166563 | ... M5: =ROUND(M2*Dados!$B$5,0) -> 176115 | N5: =ROUND(SUM(B5:M5),2) -> 1955772
A6: Receita Variável - Comissão sobre Vendas Recuperadas | B6: =IF(Dados!$B$9>0,Dados!$B$9*B2,ROUND(B2*(Dados!$B$11*Dados!$B$7),2)) -> 59938.8 | C6: =IF(Dados!$B$9>0,Dados!$B$9*C2,ROUND(C2*(Dados!$B$11*Dados!$B$7),2)) -> 60894 | D6: =IF(Dados!$B$9>0,Dados!$B$9*D2,ROUND(D2*(Dados!$B$11*Dados!$B$7),2)) -> 61849.2 | E6: =IF(Dados!$B$9>0,Dados!$B$9*E2,ROUND(E2*(Dados!$B$11*Dados!$B$7),2)) -> 62804.4 | F6: =IF(Dados!$B$9>0,Dados!$B$9*F2,ROUND(F2*(Dados!$B$11*Dados!$B$7),2)) -> 63759.6 | G6: =IF(Dados!$B$9>0,Dados!$B$9*G2,ROUND(G2*(Dados!$B$11*Dados!$B$7),2)) -> 64714.8 | H6: =IF(Dados!$B$9>0,Dados!$B$9*H2,ROUND(H2*(Dados!$B$11*Dados!$B$7),2)) -> 65670 | I6: =IF(Dados!$B$9>0,Dados!$B$9*I2,ROUND(I2*(Dados!$B$11*Dados!$B$7),2)) -> 66625.2 | ... M6: =IF(Dados!$B$9>0,Dados!$B$9*M2,ROUND(M2*(Dados!$B$11*Dados!$B$7),2)) -> 70446 | N6: =ROUND(SUM(B6:M6),2) -> 782308.8
A7: Impostos | B7: =B4*Dados!$E$2 -> 33565.728 | C7: =C4*Dados!$E$2 -> 34100.64 | D7: =D4*Dados!$E$2 -> 34635.552 | E7: =E4*Dados!$E$2 -> 35170.464 | F7: =F4*Dados!$E$2 -> 35705.376 | G7: =G4*Dados!$E$2 -> 36240.288 | H7: =H4*Dados!$E$2 -> 36775.2 | I7: =I4*Dados!$E$2 -> 37310.112 | ... M7: =M4*Dados!$E$2 -> 39449.76 | N7: =ROUND(SUM(B7:M7),2) -> 438092.93
A8: Receita Líquida | B8: =B4-B7 -> 176220.07 | C8: =C4-C7 -> 179028.36 | D8: =D4-D7 -> 181836.65 | E8: =E4-E7 -> 184644.94 | F8: =F4-F7 -> 187453.22 | G8: =G4-G7 -> 190261.51 | H8: =H4-H7 -> 193069.8 | I8: =I4-I7 -> 195878.09 | ... M8: =M4-M7 -> 207111.24 | N8: =ROUND(SUM(B8:M8),2) -> 2299987.9
A9: Receita Bruta | B9: =ROUND(B8-B14-B15-B16-B17-B18,2) -> 105977.72 | C9: =ROUND(C8-C14-C15-C16-C17-C18,2) -> 107666.61 | D9: =ROUND(D8-D14-D15-D16-D17-D18,2) -> 109355.5 | E9: =ROUND(E8-E14-E15-E16-E17-E18,2) -> 111044.39 | F9: =ROUND(F8-F14-F15-F16-F17-F18,2) -> 112733.27 | G9: =ROUND(G8-G14-G15-G16-G17-G18,2) -> 114422.16 | H9: =ROUND(H8-H14-H15-H16-H17-H18,2) -> 116111.05 | I9: =ROUND(I8-I14-I15-I16-I17-I18,2) -> 117799.94 | ... M9: =ROUND(M8-M14-M15-M16-M17-M18,2) -> 124555.49 | N9: =ROUND(SUM(B9:M9),2) -> 1383199.3
A10: Margem Bruta % | B10: =IFERROR(ROUND(B9/B4,2),0) -> 0.51 | C10: =IFERROR(ROUND(C9/C4,2),0) -> 0.51 | D10: =IFERROR(ROUND(D9/D4,2),0) -> 0.51 | E10: =IFERROR(ROUND(E9/E4,2),0) -> 0.51 | F10: =IFERROR(ROUND(F9/F4,2),0) -> 0.51 | G10: =IFERROR(ROUND(G9/G4,2),0) -> 0.51 | H10: =IFERROR(ROUND(H9/H4,2),0) -> 0.51 | I10: =IFERROR(ROUND(I9/I4,2),0) -> 0.51 | ... N10: =IFERROR(ROUND(N9/N4,2),0) -> 0.51
A12: Despesa Total | B12: =ROUND(SUM(B13,B19),2) -> 131635.35 | C12: =ROUND(SUM(C13,C19),2) -> 132754.75 | D12: =ROUND(SUM(D13,D19),2) -> 133874.15 | E12: =ROUND(SUM(E13,E19),2) -> 134993.55 | F12: =ROUND(SUM(F13,F19),2) -> 136112.95 | G12: =ROUND(SUM(G13,G19),2) -> 137232.35 | H12: =ROUND(SUM(H13,H19),2) -> 138351.75 | I12: =ROUND(SUM(I13,I19),2) -> 139471.15 | ... M12: =ROUND(SUM(M13,M19),2) -> 143948.75 | N12: =ROUND(SUM(B12:M12),2) -> 1653504.6
A13: Despesas Variáveis | B13: =B14+B15+B16+B17+B18 -> 70242.35 | C13: =C14+C15+C16+C17+C18 -> 71361.75 | D13: =D14+D15+D16+D17+D18 -> 72481.15 | E13: =E14+E15+E16+E17+E18 -> 73600.55 | F13: =F14+F15+F16+F17+F18 -> 74719.95 | G13: =G14+G15+G16+G17+G18 -> 75839.35 | H13: =H14+H15+H16+H17+H18 -> 76958.75 | I13: =I14+I15+I16+I17+I18 -> 78078.15 | ... M13: =M14+M15+M16+M17+M18 -> 82555.75 | N13: =ROUND(SUM(B13:M13),2) -> 916788.6
A14: Taxas de Checkout e Plataformas | B14: =B5*Dados!$E$1 -> 7492.35 | C14: =C5*Dados!$E$1 -> 7611.75 | D14: =D5*Dados!$E$1 -> 7731.15 | E14: =E5*Dados!$E$1 -> 7850.55 | F14: =F5*Dados!$E$1 -> 7969.95 | G14: =G5*Dados!$E$1 -> 8089.35 | H14: =H5*Dados!$E$1 -> 8208.75 | I14: =I5*Dados!$E$1 -> 8328.15 | ... M14: =M5*Dados!$E$1 -> 8805.75 | N14: =ROUND(SUM(B14:M14),2) -> 97788.6
A15: Servidor | B15: =10*B2 -> 2510 | C15: =10*C2 -> 2550 | D15: =10*D2 -> 2590 | E15: =10*E2 -> 2630 | F15: =10*F2 -> 2670 | G15: =10*G2 -> 2710 | H15: =10*H2 -> 2750 | I15: =10*I2 -> 2790 | ... M15: =10*M2 -> 2950 | N15: =ROUND(SUM(B15:M15),2) -> 32760
A16: API Oficial Whatsapp | B16: =200*B2 -> 50200 | C16: =200*C2 -> 51000 | D16: =200*D2 -> 51800 | E16: =200*E2 -> 52600 | F16: =200*F2 -> 53400 | G16: =200*G2 -> 54200 | H16: =200*H2 -> 55000 | I16: =200*I2 -> 55800 | ... M16: =200*M2 -> 59000 | N16: =ROUND(SUM(B16:M16),2) -> 655200
A17: Tokens GPT | B17: =10*B2 -> 2510 | C17: =10*C2 -> 2550 | D17: =10*D2 -> 2590 | E17: =10*E2 -> 2630 | F17: =10*F2 -> 2670 | G17: =10*G2 -> 2710 | H17: =10*H2 -> 2750 | I17: =10*I2 -> 2790 | ... M17: =10*M2 -> 2950 | N17: =ROUND(SUM(B17:M17),2) -> 32760
A18: Telefone | B18: =30*B2 -> 7530 | C18: =30*C2 -> 7650 | D18: =30*D2 -> 7770 | E18: =30*E2 -> 7890 | F18: =30*F2 -> 8010 | G18: =30*G2 -> 8130 | H18: =30*H2 -> 8250 | I18: =30*I2 -> 8370 | ... M18: =30*M2 -> 8850 | N18: =ROUND(SUM(B18:M18),2) -> 98280
A19: Despesas Fixas | B19: =SUM(B20:B40) -> 61393 | C19: =SUM(C20:C40) -> 61393 | D19: =SUM(D20:D40) -> 61393 | E19: =SUM(E20:E40) -> 61393 | F19: =SUM(F20:F40) -> 61393 | G19: =SUM(G20:G40) -> 61393 | H19: =SUM(H20:H40) -> 61393 | I19: =SUM(I20:I40) -> 61393 | ... M19: =SUM(M20:M40) -> 61393 | N19: =ROUND(SUM(B19:M19),2) -> 736716
A20: Pro Labore - CEO | B20: 11100 | C20: 11100 | D20: 11100 | E20: 11100 | F20: 11100 | G20: 11100 | H20: 11100 | I20: 11100 | J20: 11100 | K20: 11100 | L20: 11100 | M20: 11100 | N20: =ROUND(SUM(B20:M20),2) -> 133200
A21: Pro Labore - Operacional | B21: 7215 | C21: 7215 | D21: 7215 | E21: 7215 | F21: 7215 | G21: 7215 | H21: 7215 | I21: 7215 | J21: 7215 | K21: 7215 | L21: 7215 | M21: 7215 | N21: =ROUND(SUM(B21:M21),2) -> 86580
A22: Pro Labore - Operacional | B22: 7215 | C22: 7215 | D22: 7215 | E22: 7215 | F22: 7215 | G22: 7215 | H22: 7215 | I22: 7215 | J22: 7215 | K22: 7215 | L22: 7215 | M22: 7215 | N22: =ROUND(SUM(B22:M22),2) -> 86580
A23: Pro Labore - Operacional | B23: 7215 | C23: 7215 | D23: 7215 | E23: 7215 | F23: 7215 | G23: 7215 | H23: 7215 | I23: 7215 | J23: 7215 | K23: 7215 | L23: 7215 | M23: 7215 | N23: =ROUND(SUM(B23:M23),2) -> 86580
A24: Auxiliar de Serviços Gerais | B24: =Dados!$E$4*Dados!$F$4 -> 1000 | C24: =Dados!$E$4*Dados!$F$4 -> 1000 | D24: =Dados!$E$4*Dados!$F$4 -> 1000 | E24: =Dados!$E$4*Dados!$F$4 -> 1000 | F24: =Dados!$E$4*Dados!$F$4 -> 1000 | G24: =Dados!$E$4*Dados!$F$4 -> 1000 | H24: =Dados!$E$4*Dados!$F$4 -> 1000 | I24: =Dados!$E$4*Dados!$F$4 -> 1000 | ... M24: =Dados!$E$4*Dados!$F$4 -> 1000 | N24: =ROUND(SUM(B24:M24),2) -> 12000
A25: Desenvolvedor | B25: =Dados!$E$5*Dados!$F$5 -> 2000 | C25: =Dados!$E$5*Dados!$F$5 -> 2000 | D25: =Dados!$E$5*Dados!$F$5 -> 2000 | E25: =Dados!$E$5*Dados!$F$5 -> 2000 | F25: =Dados!$E$5*Dados!$F$5 -> 2000 | G25: =Dados!$E$5*Dados!$F$5 -> 2000 | H25: =Dados!$E$5*Dados!$F$5 -> 2000 | I25: =Dados!$E$5*Dados!$F$5 -> 2000 | ... M25: =Dados!$E$5*Dados!$F$5 -> 2000 | N25: =ROUND(SUM(B25:M25),2) -> 24000
A26: Gestor de Tráfego | B26: =Dados!$E$6*Dados!$F$6 -> 2000 | C26: =Dados!$E$6*Dados!$F$6 -> 2000 | D26: =Dados!$E$6*Dados!$F$6 -> 2000 | E26: =Dados!$E$6*Dados!$F$6 -> 2000 | F26: =Dados!$E$6*Dados!$F$6 -> 2000 | G26: =Dados!$E$6*Dados!$F$6 -> 2000 | H26: =Dados!$E$6*Dados!$F$6 -> 2000 | I26: =Dados!$E$6*Dados!$F$6 -> 2000 | ... M26: =Dados!$E$6*Dados!$F$6 -> 2000 | N26: =ROUND(SUM(B26:M26),2) -> 24000
A27: Designer / Editor de Vídeo / Tecnologia | B27: =Dados!$E$7*Dados!$F$7 -> 2000 | C27: =Dados!$E$7*Dados!$F$7 -> 2000 | D27: =Dados!$E$7*Dados!$F$7 -> 2000 | E27: =Dados!$E$7*Dados!$F$7 -> 2000 | F27: =Dados!$E$7*Dados!$F$7 -> 2000 | G27: =Dados!$E$7*Dados!$F$7 -> 2000 | H27: =Dados!$E$7*Dados!$F$7 -> 2000 | I27: =Dados!$E$7*Dados!$F$7 -> 2000 | ... M27: =Dados!$E$7*Dados!$F$7 -> 2000 | N27: =ROUND(SUM(B27:M27),2) -> 24000
A28: Customer Success | B28: =Dados!$E$8*Dados!$F$8 -> 3000 | C28: =Dados!$E$8*Dados!$F$8 -> 3000 | D28: =Dados!$E$8*Dados!$F$8 -> 3000 | E28: =Dados!$E$8*Dados!$F$8 -> 3000 | F28: =Dados!$E$8*Dados!$F$8 -> 3000 | G28: =Dados!$E$8*Dados!$F$8 -> 3000 | H28: =Dados!$E$8*Dados!$F$8 -> 3000 | I28: =Dados!$E$8*Dados!$F$8 -> 3000 | ... M28: =Dados!$E$8*Dados!$F$8 -> 3000 | N28: =ROUND(SUM(B28:M28),2) -> 36000
A29: Vendedores | B29: =Dados!$E$9*Dados!$F$9 -> 0 | C29: =Dados!$E$9*Dados!$F$9 -> 0 | D29: =Dados!$E$9*Dados!$F$9 -> 0 | E29: =Dados!$E$9*Dados!$F$9 -> 0 | F29: =Dados!$E$9*Dados!$F$9 -> 0 | G29: =Dados!$E$9*Dados!$F$9 -> 0 | H29: =Dados!$E$9*Dados!$F$9 -> 0 | I29: =Dados!$E$9*Dados!$F$9 -> 0 | ... M29: =Dados!$E$9*Dados!$F$9 -> 0 | N29: =ROUND(SUM(B29:M29),2) -> 0
A30: CRM | B30: =Dados!$E$10*Dados!$F$10 -> 300 | C30: =Dados!$E$10*Dados!$F$10 -> 300 | D30: =Dados!$E$10*Dados!$F$10 -> 300 | E30: =Dados!$E$10*Dados!$F$10 -> 300 | F30: =Dados!$E$10*Dados!$F$10 -> 300 | G30: =Dados!$E$10*Dados!$F$10 -> 300 | H30: =Dados!$E$10*Dados!$F$10 -> 300 | I30: =Dados!$E$10*Dados!$F$10 -> 300 | ... M30: =Dados!$E$10*Dados!$F$10 -> 300 | N30: =ROUND(SUM(B30:M30),2) -> 3600
A31: Internet / Telefonia | B31: 500 | C31: 500 | D31: 500 | E31: 500 | F31: 500 | G31: 500 | H31: 500 | I31: 500 | J31: 500 | K31: 500 | L31: 500 | M31: 500 | N31: =ROUND(SUM(B31:M31),2) -> 6000
A32: Contabilidade | B32: 1000 | C32: 1000 | D32: 1000 | E32: 1000 | F32: 1000 | G32: 1000 | H32: 1000 | I32: 1000 | J32: 1000 | K32: 1000 | L32: 1000 | M32: 1000 | N32: =ROUND(SUM(B32:M32),2) -> 12000
A33: Condominio | B33: 500 | C33: 500 | D33: 500 | E33: 500 | F33: 500 | G33: 500 | H33: 500 | I33: 500 | J33: 500 | K33: 500 | L33: 500 | M33: 500 | N33: =ROUND(SUM(B33:M33),2) -> 6000
A34: Energia Elétrica | B34: 500 | C34: 500 | D34: 500 | E34: 500 | F34: 500 | G34: 500 | H34: 500 | I34: 500 | J34: 500 | K34: 500 | L34: 500 | M34: 500 | N34: =ROUND(SUM(B34:M34),2) -> 6000
A35: Aluguel | B35: 2000 | C35: 2000 | D35: 2000 | E35: 2000 | F35: 2000 | G35: 2000 | H35: 2000 | I35: 2000 | J35: 2000 | K35: 2000 | L35: 2000 | M35: 2000 | N35: =ROUND(SUM(B35:M35),2) -> 24000
A36: Google Workspace | B36: =Dados!$E$11*Dados!$F$11 -> 600 | C36: =Dados!$E$11*Dados!$F$11 -> 600 | D36: =Dados!$E$11*Dados!$F$11 -> 600 | E36: =Dados!$E$11*Dados!$F$11 -> 600 | F36: =Dados!$E$11*Dados!$F$11 -> 600 | G36: =Dados!$E$11*Dados!$F$11 -> 600 | H36: =Dados!$E$11*Dados!$F$11 -> 600 | I36: =Dados!$E$11*Dados!$F$11 -> 600 | ... M36: =Dados!$E$11*Dados!$F$11 -> 600 | N36: =ROUND(SUM(B36:M36),2) -> 7200
A37: Notion | B37: =Dados!$E$12*Dados!$F$12 -> 1200 | C37: =Dados!$E$12*Dados!$F$12 -> 1200 | D37: =Dados!$E$12*Dados!$F$12 -> 1200 | E37: =Dados!$E$12*Dados!$F$12 -> 1200 | F37: =Dados!$E$12*Dados!$F$12 -> 1200 | G37: =Dados!$E$12*Dados!$F$12 -> 1200 | H37: =Dados!$E$12*Dados!$F$12 -> 1200 | I37: =Dados!$E$12*Dados!$F$12 -> 1200 | ... M37: =Dados!$E$12*Dados!$F$12 -> 1200 | N37: =ROUND(SUM(B37:M37),2) -> 14400
A38: Treinamentos Udemy | B38: 48 | C38: 48 | D38: 48 | E38: 48 | F38: 48 | G38: 48 | H38: 48 | I38: 48 | J38: 48 | K38: 48 | L38: 48 | M38: 48 | N38: =ROUND(SUM(B38:M38),2) -> 576
A39: Jurídico | B39: 2000 | C39: 2000 | D39: 2000 | E39: 2000 | F39: 2000 | G39: 2000 | H39: 2000 | I39: 2000 | J39: 2000 | K39: 2000 | L39: 2000 | M39: 2000 | N39: =ROUND(SUM(B39:M39),2) -> 24000
A40: Anúncios Online | B40: =Dados!$E$3 -> 10000 | C40: =Dados!$E$3 -> 10000 | D40: =Dados!$E$3 -> 10000 | E40: =Dados!$E$3 -> 10000 | F40: =Dados!$E$3 -> 10000 | G40: =Dados!$E$3 -> 10000 | H40: =Dados!$E$3 -> 10000 | I40: =Dados!$E$3 -> 10000 | ... M40: =Dados!$E$3 -> 10000 | N40: =ROUND(SUM(B40:M40),2) -> 120000
A41: EBITDA = Lucro Líquido | B41: =ROUND(B9-B19,2) -> 44584.72 | C41: =ROUND(C9-C19,2) -> 46273.61 | D41: =ROUND(D9-D19,2) -> 47962.5 | E41: =ROUND(E9-E19,2) -> 49651.39 | F41: =ROUND(F9-F19,2) -> 51340.27 | G41: =ROUND(G9-G19,2) -> 53029.16 | H41: =ROUND(H9-H19,2) -> 54718.05 | I41: =ROUND(I9-I19,2) -> 56406.94 | ... M41: =ROUND(M9-M19,2) -> 63162.49 | N41: =ROUND(SUM(B41:M41),2) -> 646483.27
A42: Margem Líquida % | B42: =B41/B8 -> 0.25300591 | C42: =C41/C8 -> 0.25847084 | D42: =D41/D8 -> 0.26376696 | E42: =E41/E8 -> 0.26890199 | F42: =F41/F8 -> 0.2738831 | G42: =G41/G8 -> 0.27871722 | H42: =H41/H8 -> 0.28341071 | I42: =I41/I8 -> 0.28796963 | ... M42: =M41/M8 -> 0.30496891 | N42: =AVERAGE(B42:M42) -> 0.28025795

Sheet 2030
B1: 47484 | C1: 47515 | D1: 47543 | E1: 47574 | F1: 47604 | G1: 47635 | H1: 47665 | I1: 47696 | J1: 47727 | K1: 47757 | L1: 47788 | M1: 47818 | N1: TOTAL
A2: Usuários | B2: =ROUNDDOWN(Dados!$B$1+('2029'!M2-('2029'!M2*Dados!$B$3)),0) -> 299 | C2: =ROUNDDOWN(Dados!$B$1+(B2-(B2*Dados!$B$3)),0) -> 303 | D2: =ROUNDDOWN(Dados!$B$1+(C2-(C2*Dados!$B$3)),0) -> 306 | E2: =ROUNDDOWN(Dados!$B$1+(D2-(D2*Dados!$B$3)),0) -> 309 | F2: =ROUNDDOWN(Dados!$B$1+(E2-(E2*Dados!$B$3)),0) -> 312 | G2: =ROUNDDOWN(Dados!$B$1+(F2-(F2*Dados!$B$3)),0) -> 315 | H2: =ROUNDDOWN(Dados!$B$1+(G2-(G2*Dados!$B$3)),0) -> 318 | I2: =ROUNDDOWN(Dados!$B$1+(H2-(H2*Dados!$B$3)),0) -> 321 | J2: =ROUNDDOWN(Dados!$B$1+(I2-(I2*Dados!$B$3)),0) -> 324 | ... M2: =ROUNDDOWN(Dados!$B$1+(L2-(L2*Dados!$B$3)),0) -> 333 | N2: =M2 -> 333
A4: Receita Total | B4: =ROUND(B5+B6,2) -> 249904.2 | C4: =ROUND(C5+C6,2) -> 253247.4 | D4: =ROUND(D5+D6,2) -> 255754.8 | E4: =ROUND(E5+E6,2) -> 258262.2 | F4: =ROUND(F5+F6,2) -> 260769.6 | G4: =ROUND(G5+G6,2) -> 263277 | H4: =ROUND(H5+H6,2) -> 265784.4 | I4: =ROUND(I5+I6,2) -> 268291.8 | ... M4: =ROUND(M5+M6,2) -> 278321.4 | N4: =ROUND(SUM(B4:M4),2) -> 3173532.6
A5: Receita Fixa - Mensalidade | B5: =ROUND(B2*Dados!$B$5,0) -> 178503 | C5: =ROUND(C2*Dados!$B$5,0) -> 180891 | D5: =ROUND(D2*Dados!$B$5,0) -> 182682 | E5: =ROUND(E2*Dados!$B$5,0) -> 184473 | F5: =ROUND(F2*Dados!$B$5,0) -> 186264 | G5: =ROUND(G2*Dados!$B$5,0) -> 188055 | H5: =ROUND(H2*Dados!$B$5,0) -> 189846 | I5: =ROUND(I2*Dados!$B$5,0) -> 191637 | ... M5: =ROUND(M2*Dados!$B$5,0) -> 198801 | N5: =ROUND(SUM(B5:M5),2) -> 2266809
A6: Receita Variável - Comissão sobre Vendas Recuperadas | B6: =IF(Dados!$B$9>0,Dados!$B$9*B2,ROUND(B2*(Dados!$B$11*Dados!$B$7),2)) -> 71401.2 | C6: =IF(Dados!$B$9>0,Dados!$B$9*C2,ROUND(C2*(Dados!$B$11*Dados!$B$7),2)) -> 72356.4 | D6: =IF(Dados!$B$9>0,Dados!$B$9*D2,ROUND(D2*(Dados!$B$11*Dados!$B$7),2)) -> 73072.8 | E6: =IF(Dados!$B$9>0,Dados!$B$9*E2,ROUND(E2*(Dados!$B$11*Dados!$B$7),2)) -> 73789.2 | F6: =IF(Dados!$B$9>0,Dados!$B$9*F2,ROUND(F2*(Dados!$B$11*Dados!$B$7),2)) -> 74505.6 | G6: =IF(Dados!$B$9>0,Dados!$B$9*G2,ROUND(G2*(Dados!$B$11*Dados!$B$7),2)) -> 75222 | H6: =IF(Dados!$B$9>0,Dados!$B$9*H2,ROUND(H2*(Dados!$B$11*Dados!$B$7),2)) -> 75938.4 | I6: =IF(Dados!$B$9>0,Dados!$B$9*I2,ROUND(I2*(Dados!$B$11*Dados!$B$7),2)) -> 76654.8 | ... M6: =IF(Dados!$B$9>0,Dados!$B$9*M2,ROUND(M2*(Dados!$B$11*Dados!$B$7),2)) -> 79520.4 | N6: =ROUND(SUM(B6:M6),2) -> 906723.6
A7: Impostos | B7: =B4*Dados!$E$2 -> 39984.672 | C7: =C4*Dados!$E$2 -> 40519.584 | D7: =D4*Dados!$E$2 -> 40920.768 | E7: =E4*Dados!$E$2 -> 41321.952 | F7: =F4*Dados!$E$2 -> 41723.136 | G7: =G4*Dados!$E$2 -> 42124.32 | H7: =H4*Dados!$E$2 -> 42525.504 | I7: =I4*Dados!$E$2 -> 42926.688 | ... M7: =M4*Dados!$E$2 -> 44531.424 | N7: =ROUND(SUM(B7:M7),2) -> 507765.22
A8: Receita Líquida | B8: =B4-B7 -> 209919.53 | C8: =C4-C7 -> 212727.82 | D8: =D4-D7 -> 214834.03 | E8: =E4-E7 -> 216940.25 | F8: =F4-F7 -> 219046.46 | G8: =G4-G7 -> 221152.68 | H8: =H4-H7 -> 223258.9 | I8: =I4-I7 -> 225365.11 | ... M8: =M4-M7 -> 233789.98 | N8: =ROUND(SUM(B8:M8),2) -> 2665767.4
A9: Receita Bruta | B9: =ROUND(B8-B14-B15-B16-B17-B18,2) -> 126244.38 | C9: =ROUND(C8-C14-C15-C16-C17-C18,2) -> 127933.27 | D9: =ROUND(D8-D14-D15-D16-D17-D18,2) -> 129199.93 | E9: =ROUND(E8-E14-E15-E16-E17-E18,2) -> 130466.6 | F9: =ROUND(F8-F14-F15-F16-F17-F18,2) -> 131733.26 | G9: =ROUND(G8-G14-G15-G16-G17-G18,2) -> 132999.93 | H9: =ROUND(H8-H14-H15-H16-H17-H18,2) -> 134266.6 | I9: =ROUND(I8-I14-I15-I16-I17-I18,2) -> 135533.26 | ... M9: =ROUND(M8-M14-M15-M16-M17-M18,2) -> 140599.93 | N9: =ROUND(SUM(B9:M9),2) -> 1603176.9
A10: Margem Bruta % | B10: =IFERROR(ROUND(B9/B4,2),0) -> 0.51 | C10: =IFERROR(ROUND(C9/C4,2),0) -> 0.51 | D10: =IFERROR(ROUND(D9/D4,2),0) -> 0.51 | E10: =IFERROR(ROUND(E9/E4,2),0) -> 0.51 | F10: =IFERROR(ROUND(F9/F4,2),0) -> 0.51 | G10: =IFERROR(ROUND(G9/G4,2),0) -> 0.51 | H10: =IFERROR(ROUND(H9/H4,2),0) -> 0.51 | I10: =IFERROR(ROUND(I9/I4,2),0) -> 0.51 | ... N10: =IFERROR(ROUND(N9/N4,2),0) -> 0.51
A12: Despesa Total | B12: =ROUND(SUM(B13,B19),2) -> 152283.15 | C12: =ROUND(SUM(C13,C19),2) -> 153402.55 | D12: =ROUND(SUM(D13,D19),2) -> 154242.1 | E12: =ROUND(SUM(E13,E19),2) -> 155081.65 | F12: =ROUND(SUM(F13,F19),2) -> 155921.2 | G12: =ROUND(SUM(G13,G19),2) -> 156760.75 | H12: =ROUND(SUM(H13,H19),2) -> 157600.3 | I12: =ROUND(SUM(I13,I19),2) -> 158439.85 | ... M12: =ROUND(SUM(M13,M19),2) -> 161798.05 | N12: =ROUND(SUM(B12:M12),2) -> 1885886.4
A13: Despesas Variáveis | B13: =B14+B15+B16+B17+B18 -> 83675.15 | C13: =C14+C15+C16+C17+C18 -> 84794.55 | D13: =D14+D15+D16+D17+D18 -> 85634.1 | E13: =E14+E15+E16+E17+E18 -> 86473.65 | F13: =F14+F15+F16+F17+F18 -> 87313.2 | G13: =G14+G15+G16+G17+G18 -> 88152.75 | H13: =H14+H15+H16+H17+H18 -> 88992.3 | I13: =I14+I15+I16+I17+I18 -> 89831.85 | ... M13: =M14+M15+M16+M17+M18 -> 93190.05 | N13: =ROUND(SUM(B13:M13),2) -> 1062590.4
A14: Taxas de Checkout e Plataformas | B14: =B5*Dados!$E$1 -> 8925.15 | C14: =C5*Dados!$E$1 -> 9044.55 | D14: =D5*Dados!$E$1 -> 9134.1 | E14: =E5*Dados!$E$1 -> 9223.65 | F14: =F5*Dados!$E$1 -> 9313.2 | G14: =G5*Dados!$E$1 -> 9402.75 | H14: =H5*Dados!$E$1 -> 9492.3 | I14: =I5*Dados!$E$1 -> 9581.85 | ... M14: =M5*Dados!$E$1 -> 9940.05 | N14: =ROUND(SUM(B14:M14),2) -> 113340.45
A15: Servidor | B15: =10*B2 -> 2990 | C15: =10*C2 -> 3030 | D15: =10*D2 -> 3060 | E15: =10*E2 -> 3090 | F15: =10*F2 -> 3120 | G15: =10*G2 -> 3150 | H15: =10*H2 -> 3180 | I15: =10*I2 -> 3210 | ... M15: =10*M2 -> 3330 | N15: =ROUND(SUM(B15:M15),2) -> 37970
A16: API Oficial Whatsapp | B16: =200*B2 -> 59800 | C16: =200*C2 -> 60600 | D16: =200*D2 -> 61200 | E16: =200*E2 -> 61800 | F16: =200*F2 -> 62400 | G16: =200*G2 -> 63000 | H16: =200*H2 -> 63600 | I16: =200*I2 -> 64200 | ... M16: =200*M2 -> 66600 | N16: =ROUND(SUM(B16:M16),2) -> 759400
A17: Tokens GPT | B17: =10*B2 -> 2990 | C17: =10*C2 -> 3030 | D17: =10*D2 -> 3060 | E17: =10*E2 -> 3090 | F17: =10*F2 -> 3120 | G17: =10*G2 -> 3150 | H17: =10*H2 -> 3180 | I17: =10*I2 -> 3210 | ... M17: =10*M2 -> 3330 | N17: =ROUND(SUM(B17:M17),2) -> 37970
A18: Telefone | B18: =30*B2 -> 8970 | C18: =30*C2 -> 9090 | D18: =30*D2 -> 9180 | E18: =30*E2 -> 9270 | F18: =30*F2 -> 9360 | G18: =30*G2 -> 9450 | H18: =30*H2 -> 9540 | I18: =30*I2 -> 9630 | ... M18: =30*M2 -> 9990 | N18: =ROUND(SUM(B18:M18),2) -> 113910
A19: Despesas Fixas | B19: =SUM(B20:B40) -> 68608 | C19: =SUM(C20:C40) -> 68608 | D19: =SUM(D20:D40) -> 68608 | E19: =SUM(E20:E40) -> 68608 | F19: =SUM(F20:F40) -> 68608 | G19: =SUM(G20:G40) -> 68608 | H19: =SUM(H20:H40) -> 68608 | I19: =SUM(I20:I40) -> 68608 | ... M19: =SUM(M20:M40) -> 68608 | N19: =ROUND(SUM(B19:M19),2) -> 823296
A20: Pro Labore - CEO | B20: 13320 | C20: 13320 | D20: 13320 | E20: 13320 | F20: 13320 | G20: 13320 | H20: 13320 | I20: 13320 | J20: 13320 | K20: 13320 | L20: 13320 | M20: 13320 | N20: =ROUND(SUM(B20:M20),2) -> 159840
A21: Pro Labore - Operacional | B21: 8880 | C21: 8880 | D21: 8880 | E21: 8880 | F21: 8880 | G21: 8880 | H21: 8880 | I21: 8880 | J21: 8880 | K21: 8880 | L21: 8880 | M21: 8880 | N21: =ROUND(SUM(B21:M21),2) -> 106560
